<?xml version='1.0' encoding='utf-8'?>
<robot name="hexapod">

    <material name="black">
        <color rgba="0 0 0 1" />
    </material>

    <material name="white">
        <color rgba="1 1 1 1" />
    </material>

    <material name="orange">
        <color rgba="0.902 0.345 0 1" />
    </material>

    <link name="base_link">
        <inertial>
            <origin xyz="-1.5537100736355798e-14 -0.002038403435229488 0.006938019086318811" rpy="0.0 0.0 0.0" />
            <mass value="0.6502139585141" />
            <inertia ixx="0.0022857824718964096" iyy="0.0021948811514730725" izz="0.00445927593589297" ixy="9.76998087550513e-17" iyz="2.7823052373888905e-06" ixz="-1.4621550745303059e-18" />
        </inertial>
        <visual name="base_link_visual">
            <origin xyz="0.0 0.0 0.0" rpy="0.0 0.0 0.0" />
            <geometry>
                <mesh filename="Hexapod-Hardware/CAD/base.stl" scale="0.001 0.001 0.001" />
            </geometry>
            <material name="black" />
        </visual>
        <collision name="base_link_collision">
            <origin xyz="0.0 0.0 0.0" rpy="0.0 0.0 0.0" />
            <geometry>
                <mesh filename="Hexapod-Hardware/CAD/base.stl" scale="0.001 0.001 0.001" />
            </geometry>
        </collision>
    </link>

    <!--Leg 1 links-->
    <link name="leg1_MG996c">
        <inertial>
            <origin xyz="-0.021304026820941267 0.013879409959177549 0.008216241413562222" rpy="0.0 -0.0 0.0" />
            <mass value="0.20641808912389753" />
            <inertia ixx="3.9125183253751247e-05" iyy="3.912518931914607e-05" izz="3.601102430698445e-05" ixy="1.135155464957328e-05" iyz="5.607951873505041e-07" ixz="-5.607857783954167e-07" />
        </inertial>
        <visual name="leg1_MG996c_visual">
            <origin xyz="-0.013930002111251399 -0.007283200121891467 -2.220446049250313e-18" rpy="3.141592653589793 -0.0 2.356194490192345" />
            <geometry>
                <mesh filename="Hexapod-Hardware/CAD/MG996.stl" scale="0.001 0.001 0.001" />
            </geometry>
            <material name="black" />
        </visual>
        <collision name="leg1_MG996c_collision">
            <origin xyz="-0.013930002111251399 -0.007283200121891467 -2.220446049250313e-18" rpy="3.141592653589793 -0.0 2.356194490192345" />
            <geometry>
                <mesh filename="Hexapod-Hardware/CAD/MG996.stl" scale="0.001 0.001 0.001" />
            </geometry>
        </collision>
    </link>
    <link name="leg1_coxa">
        <inertial>
            <origin xyz="-0.018048605950277 -0.017834011443633724 -0.02487963924889388" rpy="0.0 -0.0 0.0" />
            <mass value="0.07898637744159479" />
            <inertia ixx="6.0245481740664724e-05" iyy="6.0668022033295594e-05" izz="2.4265877776945624e-05" ixy="-1.0825354473683701e-05" iyz="4.178916067895382e-06" ixz="4.235353595363469e-06" />
        </inertial>
        <visual name="leg1_coxa_visual">
            <origin xyz="-0.03747666052846265 -0.03747666052845746 0.0010000000000000054" rpy="0.0 -0.0 -0.7853981633974483" />
            <geometry>
                <mesh filename="Hexapod-Hardware/CAD/coxa_right.stl" scale="0.001 0.001 0.001" />
            </geometry>
            <material name="black" />
        </visual>
        <collision name="leg1_coxa_collision">
            <origin xyz="-0.03747666052846265 -0.03747666052845746 0.0010000000000000054" rpy="0.0 -0.0 -0.7853981633974483" />
            <geometry>
                <mesh filename="Hexapod-Hardware/CAD/coxa_right.stl" scale="0.001 0.001 0.001" />
            </geometry>
        </collision>
    </link>
    <link name="leg1_MG996f">
        <inertial>
            <origin xyz="0.024878447972789576 0.009522068265377008 0.002097446836807624" rpy="0.0 -0.0 0.0" />
            <mass value="0.20641808912389753" />
            <inertia ixx="2.777363163687565e-05" iyy="4.3243875968366954e-05" izz="4.32438892746384e-05" ixy="5.607883384320042e-07" iyz="-7.232858314518663e-06" ixz="5.607926273139098e-07" />
        </inertial>
        <visual name="leg1_MG996f_visual">
            <origin xyz="0.004700000000000009 0.010606600931670993 -0.010606605868277549" rpy="2.356194490192345 5.551115123125783e-17 5.551115123125783e-17" />
            <geometry>
                <mesh filename="Hexapod-Hardware/CAD/MG996.stl" scale="0.001 0.001 0.001" />
            </geometry>
            <material name="black" />
        </visual>
        <collision name="leg1_MG996f_collision">
            <origin xyz="0.004700000000000009 0.010606600931670993 -0.010606605868277549" rpy="2.356194490192345 5.551115123125783e-17 5.551115123125783e-17" />
            <geometry>
                <mesh filename="Hexapod-Hardware/CAD/MG996.stl" scale="0.001 0.001 0.001" />
            </geometry>
        </collision>
    </link>
    <link name="leg1_femur">
        <inertial>
            <origin xyz="-0.018388939255642358 0.013969821069098333 0.04552760716696073" rpy="0.0 -0.0 0.0" />
            <mass value="0.2061355014221324" />
            <inertia ixx="0.0001174197530764338" iyy="0.0001250673024832975" izz="0.00010098830847293013" ixy="3.467542980046352e-05" iyz="1.1418298465589501e-05" ixz="4.86372304098529e-06" />
        </inertial>
        <visual name="leg1_femur_visual">
            <origin xyz="-0.030405593688388067 0.03040558825519895 1.1102230246251566e-17" rpy="1.5707963267948966 -0.6108652381980156 -2.356194490192345" />
            <geometry>
                <mesh filename="Hexapod-Hardware/CAD/femur_right.stl" scale="0.001 0.001 0.001" />
            </geometry>
            <material name="black" />
        </visual>
        <collision name="leg1_femur_collision">
            <origin xyz="-0.030405593688388067 0.03040558825519895 1.1102230246251566e-17" rpy="1.5707963267948966 -0.6108652381980156 -2.356194490192345" />
            <geometry>
                <mesh filename="Hexapod-Hardware/CAD/femur_right.stl" scale="0.001 0.001 0.001" />
            </geometry>
        </collision>
    </link>
    <link name="leg1_MG996t">
        <inertial>
            <origin xyz="-0.02074495471430888 -0.006501630387875857 2.688362599201355e-09" rpy="0.0 -0.0 0.0" />
            <mass value="0.20641808912389753" />
            <inertia ixx="3.1099250465400734e-05" iyy="3.268540547845828e-05" izz="5.047674093601982e-05" ixy="4.1186963350551605e-06" iyz="6.848918567926504e-12" ixz="2.560036816874473e-12" />
        </inertial>
        <visual name="leg1_MG996t_visual">
            <origin xyz="-0.029203512090292722 0.013576447026899193 0.009750004907434402" rpy="-1.5707963267948968 -7.053861262421881e-16 -0.7853981633974486" />
            <geometry>
                <mesh filename="Hexapod-Hardware/CAD/MG996.stl" scale="0.001 0.001 0.001" />
            </geometry>
            <material name="black" />
        </visual>
        <collision name="leg1_MG996t_collision">
            <origin xyz="-0.029203512090292722 0.013576447026899193 0.009750004907434402" rpy="-1.5707963267948968 -7.053861262421881e-16 -0.7853981633974486" />
            <geometry>
                <mesh filename="Hexapod-Hardware/CAD/MG996.stl" scale="0.001 0.001 0.001" />
            </geometry>
        </collision>
    </link>
    <link name="leg1_tibia">
        <inertial>
            <origin xyz="-0.03995109484200471 -0.025800551093325356 0.013220214065198625" rpy="0.0 -0.0 0.0" />
            <mass value="0.09285304614043148" />
            <inertia ixx="5.1309863875431536e-05" iyy="5.664323795965707e-05" izz="9.868903018824682e-05" ixy="-4.755379767065316e-05" iyz="5.1937257807535475e-06" ixz="6.548081736350214e-06" />
        </inertial>
        <visual name="leg1_tibia_visual">
            <origin xyz="-0.03648670888047988 -0.026162954811762767 -0.004750004907434402" rpy="-0.7853981633974483 -1.570796326794896 0" />
            <geometry>
                <mesh filename="Hexapod-Hardware/CAD/tibia_right.stl" scale="0.001 0.001 0.001" />
            </geometry>
            <material name="black" />
        </visual>
        <collision name="leg1_tibia_collision">
            <origin xyz="-0.03648670888047988 -0.026162954811762767 -0.004750004907434402" rpy="-0.7853981633974483 -1.570796326794896 0" />
            <geometry>
                <mesh filename="Hexapod-Hardware/CAD/tibia_right.stl" scale="0.001 0.001 0.001" />
            </geometry>
        </collision>
    </link>
    <link name="leg1_shield">
        <inertial>
            <origin xyz="0.0079568594346555 0.02272417345231009 -0.022724629731227283" rpy="0.0 -0.0 0.0" />
            <mass value="0.09400422482344938" />
            <inertia ixx="0.00011235877990886396" iyy="5.845313432736128e-05" izz="5.845346139379858e-05" ixy="2.724396003726077e-06" iyz="4.05725750517341e-05" ixz="-2.724973858622389e-06" />
        </inertial>
        <visual name="leg1_shield_visual">
            <origin xyz="-4.907434369982866e-09 0.0014142156932291528 0.02687005387244227" rpy="1.5707963267948968 0.7853981633974483 1.570796326794897" />
            <geometry>
                <mesh filename="Hexapod-Hardware/CAD/shield.stl" scale="0.001 0.001 0.001" />
            </geometry>
            <material name="orange" />
        </visual>
        <collision name="leg1_shield_collision">
            <origin xyz="-4.907434369982866e-09 0.0014142156932291528 0.02687005387244227" rpy="1.5707963267948968 0.7853981633974483 1.570796326794897" />
            <geometry>
                <mesh filename="Hexapod-Hardware/CAD/shield.stl" scale="0.001 0.001 0.001" />
            </geometry>
        </collision>
    </link>

    <!--Leg 2 links-->
    <link name="leg2_MG996c">
        <inertial>
            <origin xyz="-0.02487844797278954 -0.00524999778092809 0.008216241413562222" rpy="0.0 -0.0 0.0" />
            <mass value="0.20641808912389753" />
            <inertia ixx="2.7773631636875524e-05" iyy="5.047674093602156e-05" izz="3.601102430698445e-05" ixy="-3.0326974862454255e-12" iyz="6.653135933115804e-12" ixz="-7.93077506528665e-07" />
        </inertial>
        <visual name="leg2_MG996c_visual">
            <origin xyz="-0.00469999999999998 -0.014999999999999914 -2.220446049250313e-18" rpy="3.141592653589793 -0.0 3.141592653589793" />
            <geometry>
                <mesh filename="Hexapod-Hardware/CAD/MG996.stl" scale="0.001 0.001 0.001" />
            </geometry>
            <material name="black" />
        </visual>
        <collision name="leg2_MG996c_collision">
            <origin xyz="-0.00469999999999998 -0.014999999999999914 -2.220446049250313e-18" rpy="3.141592653589793 -0.0 3.141592653589793" />
            <geometry>
                <mesh filename="Hexapod-Hardware/CAD/MG996.stl" scale="0.001 0.001 0.001" />
            </geometry>
        </collision>
    </link>
    <link name="leg2_coxa">
        <inertial>
            <origin xyz="-0.025372840494155984 0.00015174123084907715 -0.02487963924889388" rpy="0.0 -0.0 0.0" />
            <mass value="0.07898637744159479" />
            <inertia ixx="4.963139741329645e-05" iyy="7.128210636066343e-05" izz="2.4265877776945407e-05" ixy="2.112701463155309e-07" iyz="-3.990735838609893e-08" ixz="5.949787137622529e-06" />
        </inertial>
        <visual name="leg2_coxa_visual">
            <origin xyz="-0.05299999999999999 -9.428360203700333e-17 0.0010000000000000054" rpy="0.0 -0.0 -1.5707963267948966" />
            <geometry>
                <mesh filename="Hexapod-Hardware/CAD/coxa_right.stl" scale="0.001 0.001 0.001" />
            </geometry>
            <material name="black" />
        </visual>
        <collision name="leg2_coxa_collision">
            <origin xyz="-0.05299999999999999 -9.428360203700333e-17 0.0010000000000000054" rpy="0.0 -0.0 -1.5707963267948966" />
            <geometry>
                <mesh filename="Hexapod-Hardware/CAD/coxa_right.stl" scale="0.001 0.001 0.001" />
            </geometry>
        </collision>
    </link>
    <link name="leg2_MG996t">
        <inertial>
            <origin xyz="-0.010071550349059244 -0.019266241413562125 2.6883626169649235e-09" rpy="0.0 -0.0 0.0" />
            <mass value="0.20641808912389753" />
            <inertia ixx="2.7773631636875e-05" iyy="3.601102430698423e-05" izz="5.047674093602069e-05" ixy="-7.930775065286854e-07" iyz="6.653135934699388e-12" ixz="-3.0326969234495404e-12" />
        </inertial>
        <visual name="leg2_MG996t_visual">
            <origin xyz="-0.030249998321848822 -0.0110499999999999 0.00975000490743443" rpy="-1.5707963267948966 -5.608327010386881e-16 -6.123233995736767e-17" />
            <geometry>
                <mesh filename="Hexapod-Hardware/CAD/MG996.stl" scale="0.001 0.001 0.001" />
            </geometry>
            <material name="black" />
        </visual>
        <collision name="leg2_MG996t_collision">
            <origin xyz="-0.030249998321848822 -0.0110499999999999 0.00975000490743443" rpy="-1.5707963267948966 -5.608327010386881e-16 -6.123233995736767e-17" />
            <geometry>
                <mesh filename="Hexapod-Hardware/CAD/MG996.stl" scale="0.001 0.001 0.001" />
            </geometry>
        </collision>
    </link>
    <link name="leg2_femur">
        <inertial>
            <origin xyz="-0.0031247845947251916 0.02288109973213494 0.04552760716696073" rpy="0.0 -0.0 0.0" />
            <mass value="0.2061355014221324" />
            <inertia ixx="0.00015591895758032938" iyy="8.656809797940278e-05" izz="0.00010098830847293013" ixy="3.823774703431824e-06" iyz="4.634784730536001e-06" ixz="1.1513127818724676e-05" />
        </inertial>
        <visual name="leg2_femur_visual">
            <origin xyz="0.0 0.0429999999999999 1.1102230246251566e-17" rpy="1.5707963267948966 -0.6108652381980154 -3.141592653589793" />
            <geometry>
                <mesh filename="Hexapod-Hardware/CAD/femur_right.stl" scale="0.001 0.001 0.001" />
            </geometry>
            <material name="black" />
        </visual>
        <collision name="leg2_femur_collision">
            <origin xyz="0.0 0.0429999999999999 1.1102230246251566e-17" rpy="1.5707963267948966 -0.6108652381980154 -3.141592653589793" />
            <geometry>
                <mesh filename="Hexapod-Hardware/CAD/femur_right.stl" scale="0.001 0.001 0.001" />
            </geometry>
        </collision>
    </link>
    <link name="leg2_MG996f">
        <inertial>
            <origin xyz="0.024878447972789576 0.00821624141356212 -0.00524999778092818" rpy="0.0 -0.0 0.0" />
            <mass value="0.20641808912389753" />
            <inertia ixx="2.7773631636876083e-05" iyy="3.601102430698553e-05" izz="5.047674093602181e-05" ixy="7.930775065286857e-07" iyz="6.653135927923125e-12" ixz="3.0326974655506267e-12" />
        </inertial>
        <visual name="leg2_MG996f_visual">
            <origin xyz="0.004700000000000009 -1.0325074129013956e-16 -0.015" rpy="1.5707963267948968 -0.0 3.749399456654644e-33" />
            <geometry>
                <mesh filename="Hexapod-Hardware/CAD/MG996.stl" scale="0.001 0.001 0.001" />
            </geometry>
            <material name="black" />
        </visual>
        <collision name="leg2_MG996f_collision">
            <origin xyz="0.004700000000000009 -1.0325074129013956e-16 -0.015" rpy="1.5707963267948968 -0.0 3.749399456654644e-33" />
            <geometry>
                <mesh filename="Hexapod-Hardware/CAD/MG996.stl" scale="0.001 0.001 0.001" />
            </geometry>
        </collision>
    </link>
    <link name="leg2_tibia">
        <inertial>
            <origin xyz="-0.04649343100105618 0.010005948932875887 0.002720214065198672" rpy="0.0 -0.0 0.0" />
            <mass value="0.09285304614043148" />
            <inertia ixx="6.42275324689147e-06" iyy="0.00010153034858819679" izz="9.86890301882459e-05" ixy="2.6666870421129167e-06" iyz="-9.576742803426859e-07" ixz="8.302711718731438e-06" />
        </inertial>
        <visual name="leg2_tibia_visual">
            <origin xyz="-0.0442999983218488 0.0072999999999999 -0.015250004907434373" rpy="-1.5707963267948966 -1.570796326794896 0" />
            <geometry>
                <mesh filename="Hexapod-Hardware/CAD/tibia_right.stl" scale="0.001 0.001 0.001" />
            </geometry>
            <material name="black" />
        </visual>
        <collision name="leg2_tibia_collision">
            <origin xyz="-0.0442999983218488 0.0072999999999999 -0.015250004907434373" rpy="-1.5707963267948966 -1.570796326794896 0" />
            <geometry>
                <mesh filename="Hexapod-Hardware/CAD/tibia_right.stl" scale="0.001 0.001 0.001" />
            </geometry>
        </collision>
    </link>
    <link name="leg2_shield">
        <inertial>
            <origin xyz="0.007956859434655553 -3.214487111319331e-07 -0.032137151919441255" rpy="0.0 -0.0 0.0" />
            <mass value="0.09400422482344938" />
            <inertia ixx="0.00011235877990886352" iyy="9.902587291231446e-05" izz="1.788072280884496e-05" ixy="-4.0860511540719057e-10" iyz="1.6353321903020065e-10" ixz="-3.853286382860194e-06" />
        </inertial>
        <visual name="leg2_shield_visual">
            <origin xyz="-4.9074343344557295e-09 0.01999999999999988 0.018000000805759805" rpy="4.295254065614839e-32 1.5707963267948966 0" />
            <geometry>
                <mesh filename="Hexapod-Hardware/CAD/shield.stl" scale="0.001 0.001 0.001" />
            </geometry>
            <material name="orange" />
        </visual>
        <collision name="leg2_shield_collision">
            <origin xyz="-4.9074343344557295e-09 0.01999999999999988 0.018000000805759805" rpy="4.295254065614839e-32 1.5707963267948966 0" />
            <geometry>
                <mesh filename="Hexapod-Hardware/CAD/shield.stl" scale="0.001 0.001 0.001" />
            </geometry>
        </collision>
    </link>

    <!--Leg 3 links-->
    <link name="leg3_MG996c">
        <inertial>
            <origin xyz="-0.013879409959183865 -0.02130402682093723 0.008216241413562222" rpy="0.0 -0.0 0.0" />
            <mass value="0.20641808912389753" />
            <inertia ixx="3.912518931914618e-05" iyy="3.9125183253751247e-05" izz="3.60110243069851e-05" ixy="-1.1351554649573063e-05" iyz="-5.607857783954167e-07" ixz="-5.60795187350477e-07" />
        </inertial>
        <visual name="leg3_MG996c_visual">
            <origin xyz="0.007283200121885147 -0.013930002111247354 -2.220446049250313e-18" rpy="3.141592653589793 -0.0 -2.356194490192345" />
            <geometry>
                <mesh filename="Hexapod-Hardware/CAD/MG996.stl" scale="0.001 0.001 0.001" />
            </geometry>
            <material name="black" />
        </visual>
        <collision name="leg3_MG996c_collision">
            <origin xyz="0.007283200121885147 -0.013930002111247354 -2.220446049250313e-18" rpy="3.141592653589793 -0.0 -2.356194490192345" />
            <geometry>
                <mesh filename="Hexapod-Hardware/CAD/MG996.stl" scale="0.001 0.001 0.001" />
            </geometry>
        </collision>
    </link>
    <link name="leg3_coxa">
        <inertial>
            <origin xyz="-0.017834011443640056 0.018048605950272946 -0.02487963924889388" rpy="0.0 -0.0 0.0" />
            <mass value="0.07898637744159479" />
            <inertia ixx="6.0668022033295486e-05" iyy="6.024548174066451e-05" izz="2.4265877776945407e-05" ixy="1.0825354473683701e-05" iyz="-4.235353595363456e-06" ixz="4.178916067895357e-06" />
        </inertial>
        <visual name="leg3_coxa_visual">
            <origin xyz="-0.03747666052846379 0.0374766605284586 0.0010000000000000054" rpy="0.0 -0.0 -2.356194490192345" />
            <geometry>
                <mesh filename="Hexapod-Hardware/CAD/coxa_right.stl" scale="0.001 0.001 0.001" />
            </geometry>
            <material name="black" />
        </visual>
        <collision name="leg3_coxa_collision">
            <origin xyz="-0.03747666052846379 0.0374766605284586 0.0010000000000000054" rpy="0.0 -0.0 -2.356194490192345" />
            <geometry>
                <mesh filename="Hexapod-Hardware/CAD/coxa_right.stl" scale="0.001 0.001 0.001" />
            </geometry>
        </collision>
    </link>
    <link name="leg3_MG996f">
        <inertial>
            <origin xyz="0.024878447972789576 0.002097446836803627 -0.009522068265370703" rpy="0.0 -0.0 0.0" />
            <mass value="0.20641808912389753" />
            <inertia ixx="2.7773631636876517e-05" iyy="4.3243889274639053e-05" izz="4.3243875968366954e-05" ixy="5.60792627313903e-07" iyz="7.232858314518663e-06" ixz="-5.607883384319974e-07" />
        </inertial>
        <visual name="leg3_MG996f_visual">
            <origin xyz="0.004700000000000009 -0.010606605868281545 -0.01060660093166467" rpy="0.7853981633974483 -0.0 0.0" />
            <geometry>
                <mesh filename="Hexapod-Hardware/CAD/MG996.stl" scale="0.001 0.001 0.001" />
            </geometry>
            <material name="black" />
        </visual>
        <collision name="leg3_MG996f_collision">
            <origin xyz="0.004700000000000009 -0.010606605868281545 -0.01060660093166467" rpy="0.7853981633974483 -0.0 0.0" />
            <geometry>
                <mesh filename="Hexapod-Hardware/CAD/MG996.stl" scale="0.001 0.001 0.001" />
            </geometry>
        </collision>
    </link>
    <link name="leg3_femur">
        <inertial>
            <origin xyz="0.013969821069091976 0.018388939255638323 0.04552760716696073" rpy="0.0 -0.0 0.0" />
            <mass value="0.2061355014221324" />
            <inertia ixx="0.00012506730248329836" iyy="0.0001174197530764338" izz="0.000100988308472931" ixy="-3.467542980046352e-05" iyz="-4.863723040985941e-06" ixz="1.1418298465589068e-05" />
        </inertial>
        <visual name="leg3_femur_visual">
            <origin xyz="0.03040558825519259 0.030405593688384053 1.1102230246251566e-17" rpy="1.5707963267948966 -0.6108652381980152 2.356194490192345" />
            <geometry>
                <mesh filename="Hexapod-Hardware/CAD/femur_right.stl" scale="0.001 0.001 0.001" />
            </geometry>
            <material name="black" />
        </visual>
        <collision name="leg3_femur_collision">
            <origin xyz="0.03040558825519259 0.030405593688384053 1.1102230246251566e-17" rpy="1.5707963267948966 -0.6108652381980152 2.356194490192345" />
            <geometry>
                <mesh filename="Hexapod-Hardware/CAD/femur_right.stl" scale="0.001 0.001 0.001" />
            </geometry>
        </collision>
    </link>
    <link name="leg3_MG996t">
        <inertial>
            <origin xyz="0.005794523434903134 0.0200378477613385 -2.6883626524920603e-09" rpy="0.0 -0.0 0.0" />
            <mass value="0.20641808912389753" />
            <inertia ixx="3.268540547845915e-05" iyy="3.109925046540159e-05" izz="5.047674093601982e-05" ixy="4.118696335054726e-06" iyz="2.5600368163814726e-12" ixz="6.848918349121394e-12" />
        </inertial>
        <visual name="leg3_MG996t_visual">
            <origin xyz="-0.014283553979871896 0.028496405137322347 -0.009750004907434481" rpy="1.5707963267948966 -3.885780586188048e-16 -0.7853981633974485" />
            <geometry>
                <mesh filename="Hexapod-Hardware/CAD/MG996.stl" scale="0.001 0.001 0.001" />
            </geometry>
            <material name="black" />
        </visual>
        <collision name="leg3_MG996t_collision">
            <origin xyz="-0.014283553979871896 0.028496405137322347 -0.009750004907434481" rpy="1.5707963267948966 -3.885780586188048e-16 -0.7853981633974485" />
            <geometry>
                <mesh filename="Hexapod-Hardware/CAD/MG996.stl" scale="0.001 0.001 0.001" />
            </geometry>
        </collision>
    </link>
    <link name="leg3_tibia">
        <inertial>
            <origin xyz="-0.025800548046298104 0.03995109788903433 0.013220214065198573" rpy="0.0 -0.0 0.0" />
            <mass value="0.09285304614043148" />
            <inertia ixx="5.664323795965664e-05" iyy="5.130986387543064e-05" izz="9.86890301882459e-05" ixy="4.7553797670652495e-05" iyz="-6.548081736349994e-06" ixz="5.1937257807537635e-06" />
        </inertial>
        <visual name="leg3_tibia_visual">
            <origin xyz="-0.026162951764735497 0.0364867119275095 -0.004750004907434464" rpy="-2.356194490192345 -1.5707963267948963 0" />
            <geometry>
                <mesh filename="Hexapod-Hardware/CAD/tibia_right.stl" scale="0.001 0.001 0.001" />
            </geometry>
            <material name="black" />
        </visual>
        <collision name="leg3_tibia_collision">
            <origin xyz="-0.026162951764735497 0.0364867119275095 -0.004750004907434464" rpy="-2.356194490192345 -1.5707963267948963 0" />
            <geometry>
                <mesh filename="Hexapod-Hardware/CAD/tibia_right.stl" scale="0.001 0.001 0.001" />
            </geometry>
        </collision>
    </link>
    <link name="leg3_shield">
        <inertial>
            <origin xyz="0.007956859434655428 -0.022724626684197596 -0.022724166499337298" rpy="-2.7369110631344083e-48 6.842277657836022e-49 -6.842277657836022e-49" />
            <mass value="0.09400422482344938" />
            <inertia ixx="0.0001123587799088648" iyy="5.8453461393798565e-05" izz="5.8453134327360844e-05" ixy="-2.724973858622388e-06" iyz="-4.0572575051734526e-05" ixz="-2.7243960037262936e-06" />
        </inertial>
        <visual name="leg3_shield_visual">
            <origin xyz="-4.907434458800708e-09 0.02687005691947199 -0.0014142087402563774" rpy="-1.5707963267948966 0.7853981633974483 -1.5707963267948966" />
            <geometry>
                <mesh filename="Hexapod-Hardware/CAD/shield.stl" scale="0.001 0.001 0.001" />
            </geometry>
            <material name="orange" />
        </visual>
        <collision name="leg3_shield_collision">
            <origin xyz="-4.907434458800708e-09 0.02687005691947199 -0.0014142087402563774" rpy="-1.5707963267948966 0.7853981633974483 -1.5707963267948966" />
            <geometry>
                <mesh filename="Hexapod-Hardware/CAD/shield.stl" scale="0.001 0.001 0.001" />
            </geometry>
        </collision>
    </link>

    <!--Leg 4 links-->
    <link name="leg4_MG996c">
        <inertial>
            <origin xyz="0.021304026820941204 -0.01387940995917754 0.008216241413562222" rpy="0.0 -0.0 0.0" />
            <mass value="0.20641808912389753" />
            <inertia ixx="3.912518325375103e-05" iyy="3.912518931914607e-05" izz="3.601102430698445e-05" ixy="1.1351554649573063e-05" iyz="-5.60795187350477e-07" ixz="5.607857783954031e-07" />
        </inertial>
        <visual name="leg4_MG996c_visual">
            <origin xyz="0.013930002111251337 0.007283200121891475 -2.220446049250313e-18" rpy="3.141592653589793 -0.0 -0.7853981633974483" />
            <geometry>
                <mesh filename="Hexapod-Hardware/CAD/MG996.stl" scale="0.001 0.001 0.001" />
            </geometry>
            <material name="black" />
        </visual>
        <collision name="leg4_MG996c_collision">
            <origin xyz="0.013930002111251337 0.007283200121891475 -2.220446049250313e-18" rpy="3.141592653589793 -0.0 -0.7853981633974483" />
            <geometry>
                <mesh filename="Hexapod-Hardware/CAD/MG996.stl" scale="0.001 0.001 0.001" />
            </geometry>
        </collision>
    </link>
    <link name="leg4_coxa">
        <inertial>
            <origin xyz="0.017834011443634532 0.018048605950276093 -0.024879639248893887" rpy="0.0 -0.0 0.0" />
            <mass value="0.07898637744159481" />
            <inertia ixx="6.066802203296567e-05" iyy="6.024548174035898e-05" izz="2.4265877776310065e-05" ixy="-1.0825354473048359e-05" iyz="-4.23535359535696e-06" ixz="-4.178916067901856e-06" />
        </inertial>
        <visual name="leg4_coxa_visual">
            <origin xyz="0.03747666052846258 0.037476660528457446 0.0010000000000000054" rpy="3.141592653589793 -0.0 -0.7853981633974485" />
            <geometry>
                <mesh filename="Hexapod-Hardware/CAD/coxa_left.stl" scale="0.001 0.001 0.001" />
            </geometry>
            <material name="black" />
        </visual>
        <collision name="leg4_coxa_collision">
            <origin xyz="0.03747666052846258 0.037476660528457446 0.0010000000000000054" rpy="3.141592653589793 -0.0 -0.7853981633974485" />
            <geometry>
                <mesh filename="Hexapod-Hardware/CAD/coxa_left.stl" scale="0.001 0.001 0.001" />
            </geometry>
        </collision>
    </link>
    <link name="leg4_MG996f">
        <inertial>
            <origin xyz="-0.024521552027210444 -0.009522073698561045 -0.0020974514036133664" rpy="0.0 -0.0 0.0" />
            <mass value="0.20641808912389753" />
            <inertia ixx="2.7773631636876517e-05" iyy="4.324387596836739e-05" izz="4.324388927463927e-05" ixy="-5.607883384319703e-07" iyz="-7.2328583145190965e-06" ixz="-5.607926273139301e-07" />
        </inertial>
        <visual name="leg4_MG996f_visual">
            <origin xyz="-0.04470000000000001 -0.010606606364855012 0.010606601301471806" rpy="-0.7853981633974485 -5.5511151231257815e-17 -1.1102230246251563e-16" />
            <geometry>
                <mesh filename="Hexapod-Hardware/CAD/MG996.stl" scale="0.001 0.001 0.001" />
            </geometry>
            <material name="black" />
        </visual>
        <collision name="leg4_MG996f_collision">
            <origin xyz="-0.04470000000000001 -0.010606606364855012 0.010606601301471806" rpy="-0.7853981633974485 -5.5511151231257815e-17 -1.1102230246251563e-16" />
            <geometry>
                <mesh filename="Hexapod-Hardware/CAD/MG996.stl" scale="0.001 0.001 0.001" />
            </geometry>
        </collision>
    </link>
    <link name="leg4_femur">
        <inertial>
            <origin xyz="-0.013969821069090945 0.018388939255639673 0.045527607166963115" rpy="0.0 -0.0 0.0" />
            <mass value="0.2061355014221325" />
            <inertia ixx="0.00012506730248260448" iyy="0.00011741975307571473" izz="0.00010098830847278525" ixy="3.4675429800533335e-05" iyz="-4.8637230415219685e-06" ixz="-1.141829846611317e-05" />
        </inertial>
        <visual name="leg4_femur_visual">
            <origin xyz="-0.03040558825519396 0.03040559368838304 2.4424906541753444e-17" rpy="1.5707963267948963 -0.6108652381980147 0.7853981633974478" />
            <geometry>
                <mesh filename="Hexapod-Hardware/CAD/femur_left.stl" scale="0.001 0.001 0.001" />
            </geometry>
            <material name="black" />
        </visual>
        <collision name="leg4_femur_collision">
            <origin xyz="-0.03040558825519396 0.03040559368838304 2.4424906541753444e-17" rpy="1.5707963267948963 -0.6108652381980147 0.7853981633974478" />
            <geometry>
                <mesh filename="Hexapod-Hardware/CAD/femur_left.stl" scale="0.001 0.001 0.001" />
            </geometry>
        </collision>
    </link>
    <link name="leg4_MG996t">
        <inertial>
            <origin xyz="-0.006501630387870669 -0.020744954714303744 7.126506247345787e-09" rpy="-1.5407439555097887e-33 1.232595164407831e-32 0.0" />
            <mass value="0.20641808912389753" />
            <inertia ixx="3.2685405478459134e-05" iyy="3.109925046540072e-05" izz="5.0476740936021544e-05" ixy="4.118696335055157e-06" iyz="-2.560036818518699e-12" ixz="-6.8489181349411156e-12" />
        </inertial>
        <visual name="leg4_MG996t_visual">
            <origin xyz="0.013576447026904397 -0.029203512090287608 -0.009749995092565564" rpy="1.5707963267948968 3.67395003908284e-16 2.3561944901923453" />
            <geometry>
                <mesh filename="Hexapod-Hardware/CAD/MG996.stl" scale="0.001 0.001 0.001" />
            </geometry>
            <material name="black" />
        </visual>
        <collision name="leg4_MG996t_collision">
            <origin xyz="0.013576447026904397 -0.029203512090287608 -0.009749995092565564" rpy="1.5707963267948968 3.67395003908284e-16 2.3561944901923453" />
            <geometry>
                <mesh filename="Hexapod-Hardware/CAD/MG996.stl" scale="0.001 0.001 0.001" />
            </geometry>
        </collision>
    </link>
    <link name="leg4_tibia">
        <inertial>
            <origin xyz="0.025800551093330404 0.039951094841999525 0.013220214065198634" rpy="0.0 -0.0 -6.123514873949634e-63" />
            <mass value="0.09285304614043133" />
            <inertia ixx="5.6643237959664444e-05" iyy="5.1309863875438e-05" izz="9.868903018825977e-05" ixy="-4.7553797670659644e-05" iyz="-6.548081736350427e-06" ixz="-5.193725780753547e-06" />
        </inertial>
        <visual name="leg4_tibia_visual">
            <origin xyz="0.026162954811767863 0.03648670888047475 -0.004750004907434428" rpy="2.3561944901923457 -1.5707963267948963 0" />
            <geometry>
                <mesh filename="Hexapod-Hardware/CAD/tibia_left.stl" scale="0.001 0.001 0.001" />
            </geometry>
            <material name="black" />
        </visual>
        <collision name="leg4_tibia_collision">
            <origin xyz="0.026162954811767863 0.03648670888047475 -0.004750004907434428" rpy="2.3561944901923457 -1.5707963267948963 0" />
            <geometry>
                <mesh filename="Hexapod-Hardware/CAD/tibia_left.stl" scale="0.001 0.001 0.001" />
            </geometry>
        </collision>
    </link>
    <link name="leg4_shield">
        <inertial>
            <origin xyz="0.007956859434655482 0.0227241751341057 -0.02272462804943171" rpy="0.0 6.842277657836022e-49 0.0" />
            <mass value="0.09400422482344938" />
            <inertia ixx="0.0001123587799088648" iyy="5.845313432735996e-05" izz="5.845346139379901e-05" ixy="2.724396003726727e-06" iyz="4.0572575051735394e-05" ixz="-2.7249738586223884e-06" />
        </inertial>
        <visual name="leg4_shield_visual">
            <origin xyz="-4.907434423273571e-09 0.0014142173750247267 0.026870055554237843" rpy="1.5707963267948963 0.7853981633974475 1.5707963267948961" />
            <geometry>
                <mesh filename="Hexapod-Hardware/CAD/shield.stl" scale="0.001 0.001 0.001" />
            </geometry>
            <material name="orange" />
        </visual>
        <collision name="leg4_shield_collision">
            <origin xyz="-4.907434423273571e-09 0.0014142173750247267 0.026870055554237843" rpy="1.5707963267948963 0.7853981633974475 1.5707963267948961" />
            <geometry>
                <mesh filename="Hexapod-Hardware/CAD/shield.stl" scale="0.001 0.001 0.001" />
            </geometry>
        </collision>
    </link>

    <!--Leg 5 links-->
    <link name="leg5_MG996c">
        <inertial>
            <origin xyz="0.02487844797278954 0.005249997780928263 0.008216241413562222" rpy="0.0 -0.0 0.0" />
            <mass value="0.20641808912389753" />
            <inertia ixx="2.7773631636875538e-05" iyy="5.047674093602156e-05" izz="3.601102430698445e-05" ixy="-3.0326974931145142e-12" iyz="-6.653135931721467e-12" ixz="7.93077506528665e-07" />
        </inertial>
        <visual name="leg5_MG996c_visual">
            <origin xyz="0.00469999999999998 0.015000000000000084 -2.220446049250313e-18" rpy="3.141592653589793 -0.0 0.0" />
            <geometry>
                <mesh filename="Hexapod-Hardware/CAD/MG996.stl" scale="0.001 0.001 0.001" />
            </geometry>
            <material name="black" />
        </visual>
        <collision name="leg5_MG996c_collision">
            <origin xyz="0.00469999999999998 0.015000000000000084 -2.220446049250313e-18" rpy="3.141592653589793 -0.0 0.0" />
            <geometry>
                <mesh filename="Hexapod-Hardware/CAD/MG996.stl" scale="0.001 0.001 0.001" />
            </geometry>
        </collision>
    </link>
    <link name="leg5_coxa">
        <inertial>
            <origin xyz="0.025372840494155967 0.00015174123085516145 -0.024879639248893887" rpy="0.0 -0.0 0.0" />
            <mass value="0.07898637744159481" />
            <inertia ixx="4.9631397413614e-05" iyy="7.128210635971063e-05" izz="2.4265877776310173e-05" ixy="-2.112701463033402e-07" iyz="-3.9907358376888544e-08" ixz="-5.949787137622581e-06" />
        </inertial>
        <visual name="leg5_coxa_visual">
            <origin xyz="0.05299999999999999 -9.30026689001082e-17 0.0010000000000000054" rpy="3.141592653589793 -0.0 -1.5707963267948968" />
            <geometry>
                <mesh filename="Hexapod-Hardware/CAD/coxa_left.stl" scale="0.001 0.001 0.001" />
            </geometry>
            <material name="black" />
        </visual>
        <collision name="leg5_coxa_collision">
            <origin xyz="0.05299999999999999 -9.30026689001082e-17 0.0010000000000000054" rpy="3.141592653589793 -0.0 -1.5707963267948968" />
            <geometry>
                <mesh filename="Hexapod-Hardware/CAD/coxa_left.stl" scale="0.001 0.001 0.001" />
            </geometry>
        </collision>
    </link>
    <link name="leg5_MG996f">
        <inertial>
            <origin xyz="0.02487844797278957 -0.008216241413562128 0.005249997780928162" rpy="0.0 -0.0 0.0" />
            <mass value="0.20641808912389753" />
            <inertia ixx="2.777363163687565e-05" iyy="3.60110243069851e-05" izz="5.047674093602178e-05" ixy="-7.930775065286956e-07" iyz="6.6531359482519155e-12" ixz="-3.032697492655681e-12" />
        </inertial>
        <visual name="leg5_MG996f_visual">
            <origin xyz="0.004700000000000006 9.880984919163893e-17 0.014999999999999982" rpy="-1.5707963267948968 -1.224646799147353e-16 1.5559211466421447e-32" />
            <geometry>
                <mesh filename="Hexapod-Hardware/CAD/MG996.stl" scale="0.001 0.001 0.001" />
            </geometry>
            <material name="black" />
        </visual>
        <collision name="leg5_MG996f_collision">
            <origin xyz="0.004700000000000006 9.880984919163893e-17 0.014999999999999982" rpy="-1.5707963267948968 -1.224646799147353e-16 1.5559211466421447e-32" />
            <geometry>
                <mesh filename="Hexapod-Hardware/CAD/MG996.stl" scale="0.001 0.001 0.001" />
            </geometry>
        </collision>
    </link>
    <link name="leg5_femur">
        <inertial>
            <origin xyz="0.0031247845947285314 0.02288109973213497 0.04552760716696307" rpy="0.0 -0.0 0.0" />
            <mass value="0.2061355014221325" />
            <inertia ixx="0.0001559189575796934" iyy="8.656809797862215e-05" izz="0.00010098830847278658" ixy="-3.823774703444591e-06" iyz="4.6347847305270836e-06" ixz="-1.1513127819474294e-05" />
        </inertial>
        <visual name="leg5_femur_visual">
            <origin xyz="0.0 0.04299999999999991 4.440892098500626e-18" rpy="1.5707963267948966 -0.6108652381980154 -1.8369701987210294e-16" />
            <geometry>
                <mesh filename="Hexapod-Hardware/CAD/femur_left.stl" scale="0.001 0.001 0.001" />
            </geometry>
            <material name="black" />
        </visual>
        <collision name="leg5_femur_collision">
            <origin xyz="0.0 0.04299999999999991 4.440892098500626e-18" rpy="1.5707963267948966 -0.6108652381980154 -1.8369701987210294e-16" />
            <geometry>
                <mesh filename="Hexapod-Hardware/CAD/femur_left.stl" scale="0.001 0.001 0.001" />
            </geometry>
        </collision>
    </link>
    <link name="leg5_MG996t">
        <inertial>
            <origin xyz="0.01007155034905928 -0.01926624141356212 7.126506238464003e-09" rpy="0.0 -0.0 0.0" />
            <mass value="0.20641808912389753" />
            <inertia ixx="2.7773631636875433e-05" iyy="3.601102430698597e-05" izz="5.047674093601982e-05" ixy="7.930775065286854e-07" iyz="-6.65313593808752e-12" ixz="-3.0326969234495404e-12" />
        </inertial>
        <visual name="leg5_MG996t_visual">
            <origin xyz="0.030249998321848822 -0.011049999999999892 -0.009749995092565591" rpy="1.5707963267948966 -2.947193223346186e-16 -3.141592653589793" />
            <geometry>
                <mesh filename="Hexapod-Hardware/CAD/MG996.stl" scale="0.001 0.001 0.001" />
            </geometry>
            <material name="black" />
        </visual>
        <collision name="leg5_MG996t_collision">
            <origin xyz="0.030249998321848822 -0.011049999999999892 -0.009749995092565591" rpy="1.5707963267948966 -2.947193223346186e-16 -3.141592653589793" />
            <geometry>
                <mesh filename="Hexapod-Hardware/CAD/MG996.stl" scale="0.001 0.001 0.001" />
            </geometry>
        </collision>
    </link>
    <link name="leg5_tibia">
        <inertial>
            <origin xyz="0.046493431001056094 0.01000594893287588 0.0027202140651986363" rpy="0.0 -0.0 0.0" />
            <mass value="0.09285304614043133" />
            <inertia ixx="6.422753246891251e-06" iyy="0.00010153034858821064" izz="9.86890301882602e-05" ixy="-2.6666870421129565e-06" iyz="-9.576742803426856e-07" ixz="-8.30271171873122e-06" />
        </inertial>
        <visual name="leg5_tibia_visual">
            <origin xyz="0.04429999832184882 0.007299999999999891 -0.01525000490743441" rpy="1.5707963267948963 -1.5707963267948963 0" />
            <geometry>
                <mesh filename="Hexapod-Hardware/CAD/tibia_left.stl" scale="0.001 0.001 0.001" />
            </geometry>
            <material name="black" />
        </visual>
        <collision name="leg5_tibia_collision">
            <origin xyz="0.04429999832184882 0.007299999999999891 -0.01525000490743441" rpy="1.5707963267948963 -1.5707963267948963 0" />
            <geometry>
                <mesh filename="Hexapod-Hardware/CAD/tibia_left.stl" scale="0.001 0.001 0.001" />
            </geometry>
        </collision>
    </link>
    <link name="leg5_shield">
        <inertial>
            <origin xyz="0.007956859434655482 -3.214487109154396e-07 -0.03213715191944118" rpy="0.0 -0.0 0.0" />
            <mass value="0.09400422482344938" />
            <inertia ixx="0.00011235877990886482" iyy="9.902587291231446e-05" izz="1.7880722808844853e-05" ixy="-4.0860511541396683e-10" iyz="1.6353321898954307e-10" ixz="-3.853286382860411e-06" />
        </inertial>
        <visual name="leg5_shield_visual">
            <origin xyz="-4.907434369982866e-09 0.0200000000000001 0.018000000805759874" rpy="1.0845452443044073e-31 1.570796326794896 0" />
            <geometry>
                <mesh filename="Hexapod-Hardware/CAD/shield.stl" scale="0.001 0.001 0.001" />
            </geometry>
            <material name="orange" />
        </visual>
        <collision name="leg5_shield_collision">
            <origin xyz="-4.907434369982866e-09 0.0200000000000001 0.018000000805759874" rpy="1.0845452443044073e-31 1.570796326794896 0" />
            <geometry>
                <mesh filename="Hexapod-Hardware/CAD/shield.stl" scale="0.001 0.001 0.001" />
            </geometry>
        </collision>
    </link>

    <!--Leg 6 links-->
    <link name="leg6_MG996c">
        <inertial>
            <origin xyz="0.013879409959183846 0.021304026820937193 0.008216241413562222" rpy="0.0 -0.0 0.0" />
            <mass value="0.20641808912389753" />
            <inertia ixx="3.912518931914661e-05" iyy="3.9125183253751247e-05" izz="3.6011024306985316e-05" ixy="-1.1351554649573388e-05" iyz="5.607857783954167e-07" ixz="5.607951873505041e-07" />
        </inertial>
        <visual name="leg6_MG996c_visual">
            <origin xyz="-0.00728320012188517 0.013930002111247335 -2.220446049250313e-18" rpy="3.141592653589793 -0.0 0.7853981633974483" />
            <geometry>
                <mesh filename="Hexapod-Hardware/CAD/MG996.stl" scale="0.001 0.001 0.001" />
            </geometry>
            <material name="black" />
        </visual>
        <collision name="leg6_MG996c_collision">
            <origin xyz="-0.00728320012188517 0.013930002111247335 -2.220446049250313e-18" rpy="3.141592653589793 -0.0 0.7853981633974483" />
            <geometry>
                <mesh filename="Hexapod-Hardware/CAD/MG996.stl" scale="0.001 0.001 0.001" />
            </geometry>
        </collision>
    </link>
    <link name="leg6_coxa">
        <inertial>
            <origin xyz="0.018048605950282397 -0.017834011443630563 -0.024879639248893887" rpy="0.0 -0.0 0.0" />
            <mass value="0.07898637744159481" />
            <inertia ixx="6.024548174035909e-05" iyy="6.066802203296567e-05" izz="2.4265877776310065e-05" ixy="1.0825354473048359e-05" iyz="4.178916067901885e-06" ixz="-4.23535359535694e-06" />
        </inertial>
        <visual name="leg6_coxa_visual">
            <origin xyz="0.037476660528463754 -0.0374766605284586 0.0010000000000000054" rpy="3.141592653589793 -0.0 -2.356194490192345" />
            <geometry>
                <mesh filename="Hexapod-Hardware/CAD/coxa_left.stl" scale="0.001 0.001 0.001" />
            </geometry>
            <material name="black" />
        </visual>
        <collision name="leg6_coxa_collision">
            <origin xyz="0.037476660528463754 -0.0374766605284586 0.0010000000000000054" rpy="3.141592653589793 -0.0 -2.356194490192345" />
            <geometry>
                <mesh filename="Hexapod-Hardware/CAD/coxa_left.stl" scale="0.001 0.001 0.001" />
            </geometry>
        </collision>
    </link>
    <link name="leg6_MG996f">
        <inertial>
            <origin xyz="0.024878447972789576 -0.0020974514036173632 0.009522073698567297" rpy="0.0 -0.0 0.0" />
            <mass value="0.20641808912389753" />
            <inertia ixx="2.777363163687565e-05" iyy="4.3243889274639053e-05" izz="4.324387596836739e-05" ixy="-5.607926273139301e-07" iyz="7.232858314518663e-06" ixz="5.607883384319703e-07" />
        </inertial>
        <visual name="leg6_MG996f_visual">
            <origin xyz="0.004700000000000009 0.01060660130146781 0.010606606364861283" rpy="-2.356194490192345 1.1102230246251565e-16 -1.1102230246251565e-16" />
            <geometry>
                <mesh filename="Hexapod-Hardware/CAD/MG996.stl" scale="0.001 0.001 0.001" />
            </geometry>
            <material name="black" />
        </visual>
        <collision name="leg6_MG996f_collision">
            <origin xyz="0.004700000000000009 0.01060660130146781 0.010606606364861283" rpy="-2.356194490192345 1.1102230246251565e-16 -1.1102230246251565e-16" />
            <geometry>
                <mesh filename="Hexapod-Hardware/CAD/MG996.stl" scale="0.001 0.001 0.001" />
            </geometry>
        </collision>
    </link>
    <link name="leg6_femur">
        <inertial>
            <origin xyz="0.01838893925564591 0.01396982106909478 0.04552760716696309" rpy="0.0 -0.0 0.0" />
            <mass value="0.2061355014221325" />
            <inertia ixx="0.00011741975307571258" iyy="0.00012506730248260106" izz="0.00010098830847278534" ixy="-3.467542980053552e-05" iyz="1.141829846611274e-05" ixz="-4.863723041521754e-06" />
        </inertial>
        <visual name="leg6_femur_visual">
            <origin xyz="0.030405593688389257 0.030405588255197725 1.5543122344752193e-17" rpy="1.5707963267948966 -0.6108652381980157 -0.7853981633974482" />
            <geometry>
                <mesh filename="Hexapod-Hardware/CAD/femur_left.stl" scale="0.001 0.001 0.001" />
            </geometry>
            <material name="black" />
        </visual>
        <collision name="leg6_femur_collision">
            <origin xyz="0.030405593688389257 0.030405588255197725 1.5543122344752193e-17" rpy="1.5707963267948966 -0.6108652381980157 -0.7853981633974482" />
            <geometry>
                <mesh filename="Hexapod-Hardware/CAD/femur_left.stl" scale="0.001 0.001 0.001" />
            </geometry>
        </collision>
    </link>
    <link name="leg6_MG996t">
        <inertial>
            <origin xyz="0.020744954714310017 -0.006501630387874666 7.126506282872924e-09" rpy="0.0 -0.0 0.0" />
            <mass value="0.20641808912389753" />
            <inertia ixx="3.109925046540247e-05" iyy="3.268540547845828e-05" izz="5.047674093602245e-05" ixy="-4.118696335055157e-06" iyz="-6.848918567697872e-12" ixz="2.560036384269271e-12" />
        </inertial>
        <visual name="leg6_MG996t_visual">
            <origin xyz="0.02920351209029386 0.0135764470269004 -0.009749995092565538" rpy="1.5707963267948966 -1.110223024625156e-16 -2.356194490192345" />
            <geometry>
                <mesh filename="Hexapod-Hardware/CAD/MG996.stl" scale="0.001 0.001 0.001" />
            </geometry>
            <material name="black" />
        </visual>
        <collision name="leg6_MG996t_collision">
            <origin xyz="0.02920351209029386 0.0135764470269004 -0.009749995092565538" rpy="1.5707963267948966 -1.110223024625156e-16 -2.356194490192345" />
            <geometry>
                <mesh filename="Hexapod-Hardware/CAD/MG996.stl" scale="0.001 0.001 0.001" />
            </geometry>
        </collision>
    </link>
    <link name="leg6_tibia">
        <inertial>
            <origin xyz="0.039951094842005756 -0.025800551093326546 0.01322021406519859" rpy="0.0 -0.0 0.0" />
            <mass value="0.09285304614043133" />
            <inertia ixx="5.130986387543804e-05" iyy="5.6643237959664444e-05" izz="9.868903018825983e-05" ixy="4.755379767065945e-05" iyz="5.193725780753764e-06" ixz="-6.548081736350214e-06" />
        </inertial>
        <visual name="leg6_tibia_visual">
            <origin xyz="0.036486708880480986 -0.02616295481176401 -0.004750004907434464" rpy="0.7853981633974483 -1.5707963267948966 0" />
            <geometry>
                <mesh filename="Hexapod-Hardware/CAD/tibia_left.stl" scale="0.001 0.001 0.001" />
            </geometry>
            <material name="black" />
        </visual>
        <collision name="leg6_tibia_collision">
            <origin xyz="0.036486708880480986 -0.02616295481176401 -0.004750004907434464" rpy="0.7853981633974483 -1.5707963267948966 0" />
            <geometry>
                <mesh filename="Hexapod-Hardware/CAD/tibia_left.stl" scale="0.001 0.001 0.001" />
            </geometry>
        </collision>
    </link>
    <link name="leg6_shield">
        <inertial>
            <origin xyz="0.007956859434655428 -0.022724628049435473 -0.02272417513409943" rpy="0.0 -0.0 0.0" />
            <mass value="0.09400422482344938" />
            <inertia ixx="0.00011235877990886396" iyy="5.845346139379988e-05" izz="5.8453134327359976e-05" ixy="-2.724973858621955e-06" iyz="-4.057257505173497e-05" ixz="-2.7243960037267277e-06" />
        </inertial>
        <visual name="leg6_shield_visual">
            <origin xyz="-4.907434458800708e-09 0.02687005555423408 -0.001414217375018474" rpy="-1.5707963267948966 0.7853981633974482 -1.5707963267948966" />
            <geometry>
                <mesh filename="Hexapod-Hardware/CAD/shield.stl" scale="0.001 0.001 0.001" />
            </geometry>
            <material name="orange" />
        </visual>
        <collision name="leg6_shield_collision">
            <origin xyz="-4.907434458800708e-09 0.02687005555423408 -0.001414217375018474" rpy="-1.5707963267948966 0.7853981633974482 -1.5707963267948966" />
            <geometry>
                <mesh filename="Hexapod-Hardware/CAD/shield.stl" scale="0.001 0.001 0.001" />
            </geometry>
        </collision>
    </link>

    <!--Leg 1 joints-->
    <joint name="base_link_leg1_MG996c" type="fixed">
        <origin xyz="-0.03264053 -0.060065150000000005 0.013999999999999999" rpy="3.141592653589793 -0.0 0.0" />
        <parent link="base_link" />
        <child link="leg1_MG996c" />
    </joint>
    <joint name="leg1_coxa_joint" type="revolute">
        <origin xyz="-0.028425689999999997 0.021001069999999997 -0.01005" rpy="3.141592653589793 -0.0 0.0" />
        <parent link="leg1_MG996c" />
        <child link="leg1_coxa" />
        <axis xyz="0.0 0.0 1.0" />
        <limit lower="-1.570796" upper="1.570796" effort="1000000" velocity="1000000" />
    </joint>
    <joint name="leg1_coxa_MG996f" type="fixed">
        <origin xyz="-0.02916816000000001 -0.03906765 -0.04585" rpy="-0.0 -1.5707963267948966 0" />
        <parent link="leg1_coxa" />
        <child link="leg1_MG996f" />
    </joint>
    <joint name="leg1_femur_joint" type="revolute">
        <origin xyz="0.03495 -0.0033941100000000014 -0.010818740000000009" rpy="-0.0 1.5707963267948966 0" />
        <parent link="leg1_MG996f" />
        <child link="leg1_femur" />
        <axis xyz="0.707107 -0.707107 0.0" />
        <limit lower="-0.785398" upper="2.356194" effort="1000000" velocity="1000000" />
    </joint>
    <joint name="leg1_tibia_joint" type="revolute">
        <origin xyz="-0.020211430000000002 -0.021625650000000007 0.06344155000000001" rpy="3.141592653589793 -5.551115123125783e-17 0.0" />
        <parent link="leg1_femur" />
        <child link="leg1_MG996t" />
        <axis xyz="0.707107 0.707107 3.925232361368103e-17" />
        <limit lower="0.0" upper="1.570796" effort="1000000" velocity="1000000" />
    </joint>
    <joint name="leg1_MG996t_tibia" type="fixed">
        <origin xyz="0.0024041599999999976 -0.018031230000000013 0.005250000000000004" rpy="-3.141592653589793 -5.55111512312578e-17 0.0" />
        <parent link="leg1_MG996t" />
        <child link="leg1_tibia" />
    </joint>
    <joint name="leg1_tibia_shield" type="fixed">
        <origin xyz="-0.07392547999999997 -0.05794487000000002 0.02125" rpy="-3.222902565236662e-64 -1.5707963267948966 0" />
        <parent link="leg1_tibia" />
        <child link="leg1_shield" />
    </joint>

    <!--Leg 2 joints-->
    <joint name="base_link_leg2_MG996c" type="fixed">
        <origin xyz="-0.046200000000000005 -0.00525 0.013999999999999999" rpy="3.141592653589793 -0.0 0.0" />
        <parent link="base_link" />
        <child link="leg2_MG996c" />
    </joint>
    <joint name="leg2_coxa_joint" type="revolute">
        <origin xyz="-0.03495 -0.00525 -0.01005" rpy="3.141592653589793 -0.0 0.0" />
        <parent link="leg2_MG996c" />
        <child link="leg2_coxa" />
        <axis xyz="0.0 0.0 1.0" />
        <limit lower="-1.570796" upper="1.570796" effort="1000000" velocity="1000000" />
    </joint>
    <joint name="leg2_coxa_MG996f" type="fixed">
        <origin xyz="-0.048249999999999994 -0.006999999999999999 -0.04585" rpy="-0.0 -1.5707963267948966 0" />
        <parent link="leg2_coxa" />
        <child link="leg2_MG996f" />
    </joint>
    <joint name="leg2_femur_joint" type="revolute">
        <origin xyz="0.03495 -0.010050000000000002 -0.005250000000000004" rpy="-0.0 1.5707963267948966 0" />
        <parent link="leg2_MG996f" />
        <child link="leg2_femur" />
        <axis xyz="0.0 -1.0 0.0" />
        <limit lower="-0.785398" upper="2.356194" effort="1000000" velocity="1000000" />
    </joint>
    <joint name="leg2_tibia_joint" type="revolute">
        <origin xyz="-0.029583280000000017 -0.0009999999999999987 0.06344155000000001" rpy="3.141592653589793 -0.0 0.0" />
        <parent link="leg2_femur" />
        <child link="leg2_MG996t" />
        <axis xyz="0.0 1.0 0.0" />
        <limit lower="0.0" upper="1.570796" effort="1000000" velocity="1000000" />
    </joint>
    <joint name="leg2_MG996t_tibia" type="fixed">
        <origin xyz="0.014450000000000003 -0.01105 -0.005250000000000004" rpy="-3.141592653589793 -1.2516661846134429e-49 0.0" />
        <parent link="leg2_MG996t" />
        <child link="leg2_tibia" />
    </joint>
    <joint name="leg2_tibia_shield" type="fixed">
        <origin xyz="-0.09324641 0.0113 0.010749999999999994" rpy="-0.0 -1.5707963267948966 0" />
        <parent link="leg2_tibia" />
        <child link="leg2_shield" />
    </joint>

    <!--Leg 3 joints-->
    <joint name="base_link_leg3_MG996c" type="fixed">
        <origin xyz="-0.04006515 0.05264053 0.013999999999999999" rpy="3.141592653589793 -0.0 0.0" />
        <parent link="base_link" />
        <child link="leg3_MG996c" />
    </joint>
    <joint name="leg3_coxa_joint" type="revolute">
        <origin xyz="-0.021001069999999997 -0.028425690000000003 -0.01005" rpy="3.141592653589793 -0.0 0.0" />
        <parent link="leg3_MG996c" />
        <child link="leg3_coxa" />
        <axis xyz="0.0 0.0 1.0" />
        <limit lower="-1.570796" upper="1.570796" effort="1000000" velocity="1000000" />
    </joint>
    <joint name="leg3_coxa_MG996f" type="fixed">
        <origin xyz="-0.03906765 0.02916816000000001 -0.04585" rpy="-0.0 -1.5707963267948966 0" />
        <parent link="leg3_coxa" />
        <child link="leg3_MG996f" />
    </joint>
    <joint name="leg3_femur_joint" type="revolute">
        <origin xyz="0.03495 -0.010818740000000009 0.0033941100000000014" rpy="-0.0 1.5707963267948966 0" />
        <parent link="leg3_MG996f" />
        <child link="leg3_femur" />
        <axis xyz="-0.707107 -0.707107 0.0" />
        <limit lower="-0.785398" upper="2.356194" effort="1000000" velocity="1000000" />
    </joint>
    <joint name="leg3_tibia_joint" type="revolute">
        <origin xyz="-0.02268630999999999 0.01915077 0.06344155000000001" rpy="0.0 0.0 0.0" />
        <parent link="leg3_femur" />
        <child link="leg3_MG996t" />
        <axis xyz="-0.707107 -0.707107 0.0" />
        <limit lower="0.0" upper="1.570796" effort="1000000" velocity="1000000" />
    </joint>
    <joint name="leg3_MG996t_tibia" type="fixed">
        <origin xyz="0.017324120000000002 -0.0031112699999999906 -0.0052500000000000125" rpy="0.0 -3.050517397236834e-32 1.3465939511877539e-48" />
        <parent link="leg3_MG996t" />
        <child link="leg3_tibia" />
    </joint>
    <joint name="leg3_tibia_shield" type="fixed">
        <origin xyz="-0.05794486000000001 0.07392547999999997 0.02125" rpy="4.930380657631325e-32 -1.5707963267948966 0" />
        <parent link="leg3_tibia" />
        <child link="leg3_shield" />
    </joint>

    <!--Leg 4 joints-->
    <joint name="base_link_leg4_MG996c" type="fixed">
        <origin xyz="0.03264053 0.060065150000000005 0.013999999999999999" rpy="3.141592653589793 -0.0 0.0" />
        <parent link="base_link" />
        <child link="leg4_MG996c" />
    </joint>
    <joint name="leg4_coxa_joint" type="revolute">
        <origin xyz="0.028425689999999997 -0.021001069999999997 -0.01005" rpy="3.141592653589793 -0.0 0.0" />
        <parent link="leg4_MG996c" />
        <child link="leg4_coxa" />
        <axis xyz="0.0 0.0 1.0" />
        <limit lower="-1.570796" upper="1.570796" effort="1000000" velocity="1000000" />
    </joint>
    <joint name="leg4_coxa_MG996f" type="fixed">
        <origin xyz="0.03164303 0.02174353 0.0027500000000000037" rpy="-3.141592653589793 -1.5707963267948966 0" />
        <parent link="leg4_coxa" />
        <child link="leg4_MG996f" />
    </joint>
    <joint name="leg4_femur_joint" type="revolute">
        <origin xyz="-0.014450000000000001 0.0033941100000000014 0.010818729999999999" rpy="3.141592653589793 -1.5707963267948966 0" />
        <parent link="leg4_MG996f" />
        <child link="leg4_femur" />
        <axis xyz="0.707107 -0.7071069999999999 -4.6222332968741714e-33" />
        <limit lower="-2.356194" upper="0.785398" effort="1000000" velocity="1000000" />
    </joint>
    <joint name="leg4_tibia_joint" type="revolute">
        <origin xyz="0.021625650000000007 0.020211430000000002 0.06344155" rpy="3.141592653589793 -5.592845782213251e-17 -3.655944291150896e-49" />
        <parent link="leg4_femur" />
        <child link="leg4_MG996t" />
        <axis xyz="-0.7071069999999999 -0.7071069999999999 -3.228531091625886e-17" />
        <limit lower="0.0" upper="1.570796" effort="1000000" velocity="1000000" />
    </joint>
    <joint name="leg4_MG996t_tibia" type="fixed">
        <origin xyz="-0.018031230000000013 0.0024041600000000154 0.005250000000000004" rpy="-3.141592653589793 -5.592845782213225e-17 -4.850773625799853e-32" />
        <parent link="leg4_MG996t" />
        <child link="leg4_tibia" />
    </joint>
    <joint name="leg4_tibia_shield" type="fixed">
        <origin xyz="0.05794487000000002 0.07392548000000002 0.02124999999999999" rpy="3.141592653589793 -1.5707963267948966 0" />
        <parent link="leg4_tibia" />
        <child link="leg4_shield" />
    </joint>

    <!--Leg 5 joints-->
    <joint name="base_link_leg5_MG996c" type="fixed">
        <origin xyz="0.046200000000000005 0.00525 0.013999999999999999" rpy="3.141592653589793 -0.0 0.0" />
        <parent link="base_link" />
        <child link="leg5_MG996c" />
    </joint>
    <joint name="leg5_coxa_joint" type="revolute">
        <origin xyz="0.03495 0.00525 -0.01005" rpy="3.141592653589793 -0.0 0.0" />
        <parent link="leg5_MG996c" />
        <child link="leg5_coxa" />
        <axis xyz="0.0 0.0 1.0" />
        <limit lower="-1.570796" upper="1.570796" effort="1000000" velocity="1000000" />
    </joint>
    <joint name="leg5_coxa_MG996f" type="fixed">
        <origin xyz="0.037750000000000006 -0.006999999999999999 -0.04585" rpy="-3.141592653589793 -1.5707963267948966 0" />
        <parent link="leg5_coxa" />
        <child link="leg5_MG996f" />
    </joint>
    <joint name="leg5_femur_joint" type="revolute">
        <origin xyz="0.03495 0.010050000000000002 0.005249999999999986" rpy="-3.141592653589793 -1.5707963267948966 0" />
        <parent link="leg5_MG996f" />
        <child link="leg5_femur" />
        <axis xyz="0.0 -1.0 0.0" />
        <limit lower="-2.356194" upper="0.785398" effort="1000000" velocity="1000000" />
    </joint>
    <joint name="leg5_tibia_joint" type="revolute">
        <origin xyz="0.029583280000000017 -0.0009999999999999987 0.06344155000000001" rpy="-3.141592653589793 -3.627598386426402e-33 0.0" />
        <parent link="leg5_femur" />
        <child link="leg5_MG996t" />
        <axis xyz="0.0 -1.0 2.229123157024303e-33" />
        <limit lower="0.0" upper="1.570796" effort="1000000" velocity="1000000" />
    </joint>
    <joint name="leg5_MG996t_tibia" type="fixed">
        <origin xyz="-0.014450000000000003 -0.01105 -0.005250000000000004" rpy="3.141592653589793 -3.627598386426413e-33 8.086363567567113e-66" />
        <parent link="leg5_MG996t" />
        <child link="leg5_tibia" />
    </joint>
    <joint name="leg5_tibia_shield" type="fixed">
        <origin xyz="0.09324640999999999 0.0113 0.010749999999999994" rpy="3.141592653589793 -1.5707963267948966 0" />
        <parent link="leg5_tibia" />
        <child link="leg5_shield" />
    </joint>

    <!--Leg 6 joints-->
    <joint name="base_link_leg6_MG996c" type="fixed">
        <origin xyz="0.04006515 -0.05264053 0.013999999999999999" rpy="3.141592653589793 -0.0 0.0" />
        <parent link="base_link" />
        <child link="leg6_MG996c" />
    </joint>
    <joint name="leg6_coxa_joint" type="revolute">
        <origin xyz="0.021001069999999997 0.028425690000000003 -0.01005" rpy="3.141592653589793 -0.0 0.0" />
        <parent link="leg6_MG996c" />
        <child link="leg6_coxa" />
        <axis xyz="0.0 0.0 1.0" />
        <limit lower="-1.570796" upper="1.570796" effort="1000000" velocity="1000000" />
    </joint>
    <joint name="leg6_coxa_MG996f" type="fixed">
        <origin xyz="0.02174353 -0.03164303 -0.04585" rpy="-3.141592653589793 -1.5707963267948966 0" />
        <parent link="leg6_coxa" />
        <child link="leg6_MG996f" />
    </joint>
    <joint name="leg6_femur_joint" type="revolute">
        <origin xyz="0.03495 0.010818729999999999 -0.0033941100000000014" rpy="-3.141592653589793 -1.5707963267948966 0" />
        <parent link="leg6_MG996f" />
        <child link="leg6_femur" />
        <axis xyz="-0.707107 -0.7071070000000002 0.0" />
        <limit lower="-2.356194" upper="0.785398" effort="1000000" velocity="1000000" />
    </joint>
    <joint name="leg6_tibia_joint" type="revolute">
        <origin xyz="0.020211430000000002 -0.02162564999999999 0.06344154999999999" rpy="3.141592653589793 -0.0 -5.5511151231257815e-17" />
        <parent link="leg6_femur" />
        <child link="leg6_MG996t" />
        <axis xyz="0.707107 -0.707107 0.0" />
        <limit lower="0.0" upper="1.570796" effort="1000000" velocity="1000000" />
    </joint>
    <joint name="leg6_MG996t_tibia" type="fixed">
        <origin xyz="-0.0024041599999999976 -0.018031230000000013 0.005250000000000004" rpy="3.141592653589793 -0.0 -5.55111512312578e-17" />
        <parent link="leg6_MG996t" />
        <child link="leg6_tibia" />
    </joint>
    <joint name="leg6_tibia_shield" type="fixed">
        <origin xyz="0.07392547999999997 -0.05794487000000002 0.02125" rpy="-3.141592653589793 -1.5707963267948966 0" />
        <parent link="leg6_tibia" />
        <child link="leg6_shield" />
    </joint>
</robot>