<?xml version="1.0" ?>
<robot name="hexapod">

<material name="silver">
  <color rgba="0.700 0.700 0.700 1.000"/>
</material>

<link name="base_link">
  <inertial>
    <origin xyz="-1.5537100736355798e-14 -0.002038403435229488 0.006938019086318811" rpy="0 0 0"/>
    <mass value="0.6502139585141"/>
    <inertia ixx="0.0022857824718964096" iyy="0.002194881151473072" izz="0.004459275935892969" ixy="9.769980875505127e-17" iyz="2.7823052373888888e-06" ixz="-1.6406434097532554e-18"/>
  </inertial>
  <visual>
    <origin xyz="0 0 0" rpy="0 0 0"/>
    <geometry>
      <mesh filename="meshes/base_link.stl" scale="0.001 0.001 0.001"/>
    </geometry>
    <material name="silver"/>
    <material/>
  </visual>
  <collision>
    <origin xyz="0 0 0" rpy="0 0 0"/>
    <geometry>
      <mesh filename="meshes/base_link.stl" scale="0.001 0.001 0.001"/>
    </geometry>
  </collision>
</link>

<link name="leg_11MG996_v31Body1">
  <inertial>
    <origin xyz="0.013626879342769911 0.02105187992613748 -0.008258413777840328" rpy="0 0 0"/>
    <mass value="0.20707552542569635"/>
    <inertia ixx="3.932634648339071e-05" iyy="3.9326337147490274e-05" izz="3.618197208621701e-05" ixy="-1.1399686183516953e-05" iyz="5.600940669647157e-07" ixz="5.600929891108722e-07"/>
  </inertial>
  <visual>
    <origin xyz="0.067006 0.094431 -0.014" rpy="0 0 0"/>
    <geometry>
      <mesh filename="meshes/leg_11MG996_v31Body1.stl" scale="0.001 0.001 0.001"/>
    </geometry>
    <material name="silver"/>
    <material/>
  </visual>
  <collision>
    <origin xyz="0.067006 0.094431 -0.014" rpy="0 0 0"/>
    <geometry>
      <mesh filename="meshes/leg_11MG996_v31Body1.stl" scale="0.001 0.001 0.001"/>
    </geometry>
  </collision>
</link>

<link name="leg_21MG996_v3_31Body_31">
  <inertial>
    <origin xyz="-0.024878797849841684 0.005250000412504176 -0.008258413777840328" rpy="0 0 0"/>
    <mass value="0.20707552542569635"/>
    <inertia ixx="2.7926655631923755e-05" iyy="5.072602799895674e-05" izz="3.618197208621636e-05" ixy="-4.667950143302073e-12" iyz="7.621577802255509e-13" ixz="7.920918635484405e-07"/>
  </inertial>
  <visual>
    <origin xyz="0.0462 0.00525 -0.014" rpy="0 0 0"/>
    <geometry>
      <mesh filename="meshes/leg_21MG996_v3_31Body_31.stl" scale="0.001 0.001 0.001"/>
    </geometry>
    <material name="silver"/>
    <material/>
  </visual>
  <collision>
    <origin xyz="0.0462 0.00525 -0.014" rpy="0 0 0"/>
    <geometry>
      <mesh filename="meshes/leg_21MG996_v3_31Body_31.stl" scale="0.001 0.001 0.001"/>
    </geometry>
  </collision>
</link>

<link name="leg_31MG996_v3_81Body_81">
  <inertial>
    <origin xyz="-0.01387980549881472 0.021303806082178654 -0.008258413777840328" rpy="0 0 0"/>
    <mass value="0.20707552542569635"/>
    <inertia ixx="3.932633714748995e-05" iyy="3.932634648339006e-05" izz="3.618197208621636e-05" ixy="1.1399686183516302e-05" iyz="-5.600929891108722e-07" ixz="5.600940669647157e-07"/>
  </inertial>
  <visual>
    <origin xyz="0.040065 -0.052641 -0.014" rpy="0 0 0"/>
    <geometry>
      <mesh filename="meshes/leg_31MG996_v3_81Body_81.stl" scale="0.001 0.001 0.001"/>
    </geometry>
    <material name="silver"/>
    <material/>
  </visual>
  <collision>
    <origin xyz="0.040065 -0.052641 -0.014" rpy="0 0 0"/>
    <geometry>
      <mesh filename="meshes/leg_31MG996_v3_81Body_81.stl" scale="0.001 0.001 0.001"/>
    </geometry>
  </collision>
</link>

<link name="leg_41MG996_v3_91Body_91">
  <inertial>
    <origin xyz="0.013879806082183851 0.021303805498809565 -0.008258413777840328" rpy="0 0 0"/>
    <mass value="0.20707552542569635"/>
    <inertia ixx="3.932634648339006e-05" iyy="3.932633714749006e-05" izz="3.618197208621614e-05" ixy="-1.1399686183516627e-05" iyz="-5.600940669646886e-07" ixz="-5.60092989110818e-07"/>
  </inertial>
  <visual>
    <origin xyz="-0.040065 -0.052641 -0.014" rpy="0 0 0"/>
    <geometry>
      <mesh filename="meshes/leg_41MG996_v3_91Body_91.stl" scale="0.001 0.001 0.001"/>
    </geometry>
    <material name="silver"/>
    <material/>
  </visual>
  <collision>
    <origin xyz="-0.040065 -0.052641 -0.014" rpy="0 0 0"/>
    <geometry>
      <mesh filename="meshes/leg_41MG996_v3_91Body_91.stl" scale="0.001 0.001 0.001"/>
    </geometry>
  </collision>
</link>

<link name="leg_51MG996_v3_121Body_121">
  <inertial>
    <origin xyz="0.024878797849841768 -0.0052500004125042785 -0.008258413777840328" rpy="0 0 0"/>
    <mass value="0.20707552542569635"/>
    <inertia ixx="2.7926655631923748e-05" iyy="5.072602799895609e-05" izz="3.6181972086215706e-05" ixy="-4.667950141214595e-12" iyz="-7.621577797304395e-13" ixz="-7.920918635484134e-07"/>
  </inertial>
  <visual>
    <origin xyz="-0.0462 -0.00525 -0.014" rpy="0 0 0"/>
    <geometry>
      <mesh filename="meshes/leg_51MG996_v3_121Body_121.stl" scale="0.001 0.001 0.001"/>
    </geometry>
    <material name="silver"/>
    <material/>
  </visual>
  <collision>
    <origin xyz="-0.0462 -0.00525 -0.014" rpy="0 0 0"/>
    <geometry>
      <mesh filename="meshes/leg_51MG996_v3_121Body_121.stl" scale="0.001 0.001 0.001"/>
    </geometry>
  </collision>
</link>

<link name="leg_61MG996_v3_151Body_151">
  <inertial>
    <origin xyz="0.013879805498814707 -0.021303806082178613 -0.008258413777840328" rpy="0 0 0"/>
    <mass value="0.20707552542569635"/>
    <inertia ixx="3.932633714749038e-05" iyy="3.932634648338984e-05" izz="3.618197208621679e-05" ixy="1.1399686183516302e-05" iyz="5.600929891108451e-07" ixz="-5.600940669646615e-07"/>
  </inertial>
  <visual>
    <origin xyz="-0.040065 0.052641 -0.014" rpy="0 0 0"/>
    <geometry>
      <mesh filename="meshes/leg_61MG996_v3_151Body_151.stl" scale="0.001 0.001 0.001"/>
    </geometry>
    <material name="silver"/>
    <material/>
  </visual>
  <collision>
    <origin xyz="-0.040065 0.052641 -0.014" rpy="0 0 0"/>
    <geometry>
      <mesh filename="meshes/leg_61MG996_v3_151Body_151.stl" scale="0.001 0.001 0.001"/>
    </geometry>
  </collision>
</link>

<link name="leg_11coxa_v21">
  <inertial>
    <origin xyz="-0.018048140525324413 -0.017833546018687835 -0.024879639248893873" rpy="0 0 0"/>
    <mass value="0.07898637744159479"/>
    <inertia ixx="6.0245481740664616e-05" iyy="6.066802203329532e-05" izz="2.4265877776945624e-05" ixy="-1.0825354473683593e-05" iyz="4.178916067895392e-06" ixz="4.23535359536347e-06"/>
  </inertial>
  <visual>
    <origin xyz="0.060501 0.080501 -0.02405" rpy="0 0 0"/>
    <geometry>
      <mesh filename="meshes/leg_11coxa_v21.stl" scale="0.001 0.001 0.001"/>
    </geometry>
    <material name="silver"/>
    <material/>
  </visual>
  <collision>
    <origin xyz="0.060501 0.080501 -0.02405" rpy="0 0 0"/>
    <geometry>
      <mesh filename="meshes/leg_11coxa_v21.stl" scale="0.001 0.001 0.001"/>
    </geometry>
  </collision>
</link>

<link name="leg_11MG996_v3_21Body_21">
  <inertial>
    <origin xyz="-0.0021269599158094815 0.00955170591588797 -0.02452120215015828" rpy="0 0 0"/>
    <mass value="0.20707552542569635"/>
    <inertia ixx="4.345400080474479e-05" iyy="4.345399928042809e-05" izz="2.792665563192305e-05" ixy="7.272027956370733e-06" iyz="5.600968287769722e-07" ixz="-5.600902272985615e-07"/>
  </inertial>
  <visual>
    <origin xyz="0.089669 0.119568 -0.0268" rpy="0 0 0"/>
    <geometry>
      <mesh filename="meshes/leg_11MG996_v3_21Body_21.stl" scale="0.001 0.001 0.001"/>
    </geometry>
    <material name="silver"/>
    <material/>
  </visual>
  <collision>
    <origin xyz="0.089669 0.119568 -0.0268" rpy="0 0 0"/>
    <geometry>
      <mesh filename="meshes/leg_11MG996_v3_21Body_21.stl" scale="0.001 0.001 0.001"/>
    </geometry>
  </collision>
</link>

<link name="leg_11femur_v41">
  <inertial>
    <origin xyz="-0.018388893830689756 0.013969526494044204 0.04552760716696073" rpy="0 0 0"/>
    <mass value="0.2061355014221324"/>
    <inertia ixx="0.00011741975307643423" iyy="0.00012506730248329706" izz="0.00010098830847293013" ixy="3.467542980046395e-05" iyz="1.1418298465589068e-05" ixz="4.86372304098529e-06"/>
  </inertial>
  <visual>
    <origin xyz="0.07885 0.122962 -0.01235" rpy="0 0 0"/>
    <geometry>
      <mesh filename="meshes/leg_11femur_v41.stl" scale="0.001 0.001 0.001"/>
    </geometry>
    <material name="silver"/>
    <material/>
  </visual>
  <collision>
    <origin xyz="0.07885 0.122962 -0.01235" rpy="0 0 0"/>
    <geometry>
      <mesh filename="meshes/leg_11femur_v41.stl" scale="0.001 0.001 0.001"/>
    </geometry>
  </collision>
</link>

<link name="leg_11MG996_v3_11Body_11">
  <inertial>
    <origin xyz="-0.020774912253679792 0.006531753578017663 -4.5531993872471865e-07" rpy="0 0 0"/>
    <mass value="0.20707552542569635"/>
    <inertia ixx="3.126222199552244e-05" iyy="3.284640572261913e-05" izz="5.0726027998958256e-05" ixy="-4.12765822714687e-06" iyz="-2.761811612739251e-12" ixz="-3.839665781504853e-12"/>
  </inertial>
  <visual>
    <origin xyz="0.099061 0.144588 -0.075792" rpy="0 0 0"/>
    <geometry>
      <mesh filename="meshes/leg_11MG996_v3_11Body_11.stl" scale="0.001 0.001 0.001"/>
    </geometry>
    <material name="silver"/>
    <material/>
  </visual>
  <collision>
    <origin xyz="0.099061 0.144588 -0.075792" rpy="0 0 0"/>
    <geometry>
      <mesh filename="meshes/leg_11MG996_v3_11Body_11.stl" scale="0.001 0.001 0.001"/>
    </geometry>
  </collision>
</link>

<link name="leg_11tibia_v51">
  <inertial>
    <origin xyz="-0.03995131941705206 -0.02580026566837948 0.013219764065198578" rpy="0 0 0"/>
    <mass value="0.09285304614043148"/>
    <inertia ixx="5.1309863875431076e-05" iyy="5.664323795965707e-05" izz="9.86890301882459e-05" ixy="-4.7553797670652495e-05" iyz="5.1937257807537635e-06" ixz="6.548081736350211e-06"/>
  </inertial>
  <visual>
    <origin xyz="0.096657 0.126557 -0.070542" rpy="0 0 0"/>
    <geometry>
      <mesh filename="meshes/leg_11tibia_v51.stl" scale="0.001 0.001 0.001"/>
    </geometry>
    <material name="silver"/>
    <material/>
  </visual>
  <collision>
    <origin xyz="0.096657 0.126557 -0.070542" rpy="0 0 0"/>
    <geometry>
      <mesh filename="meshes/leg_11tibia_v51.stl" scale="0.001 0.001 0.001"/>
    </geometry>
  </collision>
</link>

<link name="leg_11shield_v21">
  <inertial>
    <origin xyz="0.022724925156179937 0.022724588877255952 0.00795640943465542" rpy="0 0 0"/>
    <mass value="0.09400422482344938"/>
    <inertia ixx="5.8453461393799446e-05" iyy="5.8453134327359976e-05" izz="0.00011235877990886309" ixy="-4.05725750517341e-05" iyz="2.724396003726511e-06" ixz="2.7249738586217383e-06"/>
  </inertial>
  <visual>
    <origin xyz="0.170583 0.184502 -0.091792" rpy="0 0 0"/>
    <geometry>
      <mesh filename="meshes/leg_11shield_v21.stl" scale="0.001 0.001 0.001"/>
    </geometry>
    <material name="silver"/>
    <material/>
  </visual>
  <collision>
    <origin xyz="0.170583 0.184502 -0.091792" rpy="0 0 0"/>
    <geometry>
      <mesh filename="meshes/leg_11shield_v21.stl" scale="0.001 0.001 0.001"/>
    </geometry>
  </collision>
</link>

<link name="leg_21coxa_v2_11">
  <inertial>
    <origin xyz="-0.025372840494155946 0.0001517412308490915 -0.024879639248893873" rpy="0 0 0"/>
    <mass value="0.07898637744159479"/>
    <inertia ixx="4.963139741329645e-05" iyy="7.128210636066343e-05" izz="2.4265877776945624e-05" ixy="2.112701463155309e-07" iyz="-3.990735838609896e-08" ixz="5.949787137622547e-06"/>
  </inertial>
  <visual>
    <origin xyz="0.08115 0.0 -0.02405" rpy="0 0 0"/>
    <geometry>
      <mesh filename="meshes/leg_21coxa_v2_11.stl" scale="0.001 0.001 0.001"/>
    </geometry>
    <material name="silver"/>
    <material/>
  </visual>
  <collision>
    <origin xyz="0.08115 0.0 -0.02405" rpy="0 0 0"/>
    <geometry>
      <mesh filename="meshes/leg_21coxa_v2_11.stl" scale="0.001 0.001 0.001"/>
    </geometry>
  </collision>
</link>

<link name="leg_21MG996_v3_51Body_51">
  <inertial>
    <origin xyz="0.005250000412504341 0.008258413777840232 -0.02452120215015828" rpy="0 0 0"/>
    <mass value="0.20707552542569635"/>
    <inertia ixx="5.072602799895642e-05" iyy="3.618197208621809e-05" izz="2.7926655631924785e-05" ixy="-7.621577590506863e-13" iyz="7.920918635483879e-07" ixz="4.667950169467711e-12"/>
  </inertial>
  <visual>
    <origin xyz="0.1294 0.007 -0.0268" rpy="0 0 0"/>
    <geometry>
      <mesh filename="meshes/leg_21MG996_v3_51Body_51.stl" scale="0.001 0.001 0.001"/>
    </geometry>
    <material name="silver"/>
    <material/>
  </visual>
  <collision>
    <origin xyz="0.1294 0.007 -0.0268" rpy="0 0 0"/>
    <geometry>
      <mesh filename="meshes/leg_21MG996_v3_51Body_51.stl" scale="0.001 0.001 0.001"/>
    </geometry>
  </collision>
</link>

<link name="leg_21femur_v4_11">
  <inertial>
    <origin xyz="-0.0031247845947251635 0.02288109973213495 0.04552760716696073" rpy="0 0 0"/>
    <mass value="0.2061355014221324"/>
    <inertia ixx="0.00015591895758032917" iyy="8.656809797940278e-05" izz="0.00010098830847293013" ixy="3.823774703431824e-06" iyz="4.634784730536015e-06" ixz="1.1513127818724243e-05"/>
  </inertial>
  <visual>
    <origin xyz="0.12415 0.01705 -0.01235" rpy="0 0 0"/>
    <geometry>
      <mesh filename="meshes/leg_21femur_v4_11.stl" scale="0.001 0.001 0.001"/>
    </geometry>
    <material name="silver"/>
    <material/>
  </visual>
  <collision>
    <origin xyz="0.12415 0.01705 -0.01235" rpy="0 0 0"/>
    <geometry>
      <mesh filename="meshes/leg_21femur_v4_11.stl" scale="0.001 0.001 0.001"/>
    </geometry>
  </collision>
</link>

<link name="leg_21MG996_v3_41Body_41">
  <inertial>
    <origin xyz="-0.010071480472007066 0.019308413777840226 -4.5531993872471865e-07" rpy="0 0 0"/>
    <mass value="0.20707552542569635"/>
    <inertia ixx="2.7926655631923918e-05" iyy="3.618197208621766e-05" izz="5.0726027998959124e-05" ixy="7.92091863548427e-07" iyz="7.621577590506863e-13" ixz="-4.6679496205903614e-12"/>
  </inertial>
  <visual>
    <origin xyz="0.153733 0.01805 -0.075792" rpy="0 0 0"/>
    <geometry>
      <mesh filename="meshes/leg_21MG996_v3_41Body_41.stl" scale="0.001 0.001 0.001"/>
    </geometry>
    <material name="silver"/>
    <material/>
  </visual>
  <collision>
    <origin xyz="0.153733 0.01805 -0.075792" rpy="0 0 0"/>
    <geometry>
      <mesh filename="meshes/leg_21MG996_v3_41Body_41.stl" scale="0.001 0.001 0.001"/>
    </geometry>
  </collision>
</link>

<link name="leg_21tibia_v5_11">
  <inertial>
    <origin xyz="-0.04649371100105615 0.010005948932875885 0.013219764065198578" rpy="0 0 0"/>
    <mass value="0.09285304614043148"/>
    <inertia ixx="6.42275324689147e-06" iyy="0.00010153034858819765" izz="9.86890301882472e-05" ixy="2.666687042112937e-06" iyz="-9.576742803426892e-07" ixz="8.302711718731221e-06"/>
  </inertial>
  <visual>
    <origin xyz="0.139283 0.007 -0.070542" rpy="0 0 0"/>
    <geometry>
      <mesh filename="meshes/leg_21tibia_v5_11.stl" scale="0.001 0.001 0.001"/>
    </geometry>
    <material name="silver"/>
    <material/>
  </visual>
  <collision>
    <origin xyz="0.139283 0.007 -0.070542" rpy="0 0 0"/>
    <geometry>
      <mesh filename="meshes/leg_21tibia_v5_11.stl" scale="0.001 0.001 0.001"/>
    </geometry>
  </collision>
</link>

<link name="leg_21shield_v2_11">
  <inertial>
    <origin xyz="0.032137461919441224 -3.214487111630193e-07 0.00795640943465542" rpy="0 0 0"/>
    <mass value="0.09400422482344938"/>
    <inertia ixx="1.788072280884507e-05" iyy="9.90258729123136e-05" izz="0.00011235877990886352" ixy="-1.6353321904375318e-10" iyz="-4.0860511540719057e-10" ixz="3.853286382860194e-06"/>
  </inertial>
  <visual>
    <origin xyz="0.23253 -0.0043 -0.091792" rpy="0 0 0"/>
    <geometry>
      <mesh filename="meshes/leg_21shield_v2_11.stl" scale="0.001 0.001 0.001"/>
    </geometry>
    <material name="silver"/>
    <material/>
  </visual>
  <collision>
    <origin xyz="0.23253 -0.0043 -0.091792" rpy="0 0 0"/>
    <geometry>
      <mesh filename="meshes/leg_21shield_v2_11.stl" scale="0.001 0.001 0.001"/>
    </geometry>
  </collision>
</link>

<link name="leg_31coxa_v2_21">
  <inertial>
    <origin xyz="-0.017834231443640082 0.018048825950272906 -0.024879639248893873" rpy="0 0 0"/>
    <mass value="0.07898637744159479"/>
    <inertia ixx="6.066802203329527e-05" iyy="6.02454817406644e-05" izz="2.4265877776945407e-05" ixy="1.0825354473683593e-05" iyz="-4.235353595363468e-06" ixz="4.1789160678953594e-06"/>
  </inertial>
  <visual>
    <origin xyz="0.061066 -0.081066 -0.02405" rpy="0 0 0"/>
    <geometry>
      <mesh filename="meshes/leg_31coxa_v2_21.stl" scale="0.001 0.001 0.001"/>
    </geometry>
    <material name="silver"/>
    <material/>
  </visual>
  <collision>
    <origin xyz="0.061066 -0.081066 -0.02405" rpy="0 0 0"/>
    <geometry>
      <mesh filename="meshes/leg_31coxa_v2_21.stl" scale="0.001 0.001 0.001"/>
    </geometry>
  </collision>
</link>

<link name="leg_31MG996_v3_61Body_61">
  <inertial>
    <origin xyz="0.009552020490935717 0.002127645340757975 -0.02452120215015828" rpy="0 0 0"/>
    <mass value="0.20707552542569635"/>
    <inertia ixx="4.345399928042809e-05" iyy="4.345400080474479e-05" izz="2.7926655631924785e-05" ixy="-7.272027956370299e-06" iyz="5.600902272985683e-07" ixz="5.600968287769654e-07"/>
  </inertial>
  <visual>
    <origin xyz="0.100134 -0.110234 -0.0268" rpy="0 0 0"/>
    <geometry>
      <mesh filename="meshes/leg_31MG996_v3_61Body_61.stl" scale="0.001 0.001 0.001"/>
    </geometry>
    <material name="silver"/>
    <material/>
  </visual>
  <collision>
    <origin xyz="0.100134 -0.110234 -0.0268" rpy="0 0 0"/>
    <geometry>
      <mesh filename="meshes/leg_31MG996_v3_61Body_61.stl" scale="0.001 0.001 0.001"/>
    </geometry>
  </collision>
</link>

<link name="leg_31femur_v4_21">
  <inertial>
    <origin xyz="0.013969841069091965 0.01838857925563825 0.04552760716696073" rpy="0 0 0"/>
    <mass value="0.2061355014221324"/>
    <inertia ixx="0.00012506730248329793" iyy="0.0001174197530764338" izz="0.000100988308472931" ixy="-3.467542980046352e-05" iyz="-4.86372304098529e-06" ixz="1.1418298465589068e-05"/>
  </inertial>
  <visual>
    <origin xyz="0.103528 -0.099416 -0.01235" rpy="0 0 0"/>
    <geometry>
      <mesh filename="meshes/leg_31femur_v4_21.stl" scale="0.001 0.001 0.001"/>
    </geometry>
    <material name="silver"/>
    <material/>
  </visual>
  <collision>
    <origin xyz="0.103528 -0.099416 -0.01235" rpy="0 0 0"/>
    <geometry>
      <mesh filename="meshes/leg_31femur_v4_21.stl" scale="0.001 0.001 0.001"/>
    </geometry>
  </collision>
</link>

<link name="leg_31MG996_v3_71Body_71">
  <inertial>
    <origin xyz="0.006532068153065423 0.020774597678628284 -4.5531993872471865e-07" rpy="0 0 0"/>
    <mass value="0.20707552542569635"/>
    <inertia ixx="3.284640572261913e-05" iyy="3.126222199552331e-05" izz="5.0726027998958256e-05" ixy="4.1276582271477374e-06" iyz="3.8396659983452874e-12" ixz="-2.7618113958988166e-12"/>
  </inertial>
  <visual>
    <origin xyz="0.125154 -0.119627 -0.075792" rpy="0 0 0"/>
    <geometry>
      <mesh filename="meshes/leg_31MG996_v3_71Body_71.stl" scale="0.001 0.001 0.001"/>
    </geometry>
    <material name="silver"/>
    <material/>
  </visual>
  <collision>
    <origin xyz="0.125154 -0.119627 -0.075792" rpy="0 0 0"/>
    <geometry>
      <mesh filename="meshes/leg_31MG996_v3_71Body_71.stl" scale="0.001 0.001 0.001"/>
    </geometry>
  </collision>
</link>

<link name="leg_31tibia_v5_21">
  <inertial>
    <origin xyz="-0.025800951093331748 0.039951004842000565 0.013219764065198578" rpy="0 0 0"/>
    <mass value="0.09285304614043148"/>
    <inertia ixx="5.664323795965794e-05" iyy="5.130986387543151e-05" izz="9.868903018824676e-05" ixy="4.755379767065293e-05" iyz="-6.548081736350211e-06" ixz="5.193725780753547e-06"/>
  </inertial>
  <visual>
    <origin xyz="0.107122 -0.117223 -0.070542" rpy="0 0 0"/>
    <geometry>
      <mesh filename="meshes/leg_31tibia_v5_21.stl" scale="0.001 0.001 0.001"/>
    </geometry>
    <material name="silver"/>
    <material/>
  </visual>
  <collision>
    <origin xyz="0.107122 -0.117223 -0.070542" rpy="0 0 0"/>
    <geometry>
      <mesh filename="meshes/leg_31tibia_v5_21.stl" scale="0.001 0.001 0.001"/>
    </geometry>
  </collision>
</link>

<link name="leg_31shield_v2_21">
  <inertial>
    <origin xyz="0.022723903452303684 -0.022724239731231444 0.00795640943465542" rpy="0 0 0"/>
    <mass value="0.09400422482344938"/>
    <inertia ixx="5.8453134327360844e-05" iyy="5.8453461393798145e-05" izz="0.00011235877990886309" ixy="4.0572575051733666e-05" iyz="-2.724973858622172e-06" ixz="2.724396003726077e-06"/>
  </inertial>
  <visual>
    <origin xyz="0.165067 -0.191148 -0.091792" rpy="0 0 0"/>
    <geometry>
      <mesh filename="meshes/leg_31shield_v2_21.stl" scale="0.001 0.001 0.001"/>
    </geometry>
    <material name="silver"/>
    <material/>
  </visual>
  <collision>
    <origin xyz="0.165067 -0.191148 -0.091792" rpy="0 0 0"/>
    <geometry>
      <mesh filename="meshes/leg_31shield_v2_21.stl" scale="0.001 0.001 0.001"/>
    </geometry>
  </collision>
</link>

<link name="leg_41coxa_v2_31">
  <inertial>
    <origin xyz="0.018048825950278118 0.017834231443634857 -0.024879639248893873" rpy="0 0 0"/>
    <mass value="0.07898637744159479"/>
    <inertia ixx="6.024548174066418e-05" iyy="6.0668022033295594e-05" izz="2.426587777694519e-05" ixy="-1.0825354473683593e-05" iyz="-4.178916067895337e-06" ixz="-4.235353595363444e-06"/>
  </inertial>
  <visual>
    <origin xyz="-0.061066 -0.081066 -0.02405" rpy="0 0 0"/>
    <geometry>
      <mesh filename="meshes/leg_41coxa_v2_31.stl" scale="0.001 0.001 0.001"/>
    </geometry>
    <material name="silver"/>
    <material/>
  </visual>
  <collision>
    <origin xyz="-0.061066 -0.081066 -0.02405" rpy="0 0 0"/>
    <geometry>
      <mesh filename="meshes/leg_41coxa_v2_31.stl" scale="0.001 0.001 0.001"/>
    </geometry>
  </collision>
</link>

<link name="leg_41MG996_v3_101Body_101">
  <inertial>
    <origin xyz="0.0021276453407631513 -0.009552020490940866 -0.02452120215015828" rpy="0 0 0"/>
    <mass value="0.20707552542569635"/>
    <inertia ixx="4.345400080474349e-05" iyy="4.345399928043026e-05" izz="2.7926655631925652e-05" ixy="7.272027956369866e-06" iyz="-5.600968287769586e-07" ixz="5.600902272985276e-07"/>
  </inertial>
  <visual>
    <origin xyz="-0.090234 -0.120134 -0.0268" rpy="0 0 0"/>
    <geometry>
      <mesh filename="meshes/leg_41MG996_v3_101Body_101.stl" scale="0.001 0.001 0.001"/>
    </geometry>
    <material name="silver"/>
    <material/>
  </visual>
  <collision>
    <origin xyz="-0.090234 -0.120134 -0.0268" rpy="0 0 0"/>
    <geometry>
      <mesh filename="meshes/leg_41MG996_v3_101Body_101.stl" scale="0.001 0.001 0.001"/>
    </geometry>
  </collision>
</link>

<link name="leg_41femur_v4_31">
  <inertial>
    <origin xyz="0.018388579255643495 -0.013969841069097141 0.04552760716696073" rpy="0 0 0"/>
    <mass value="0.2061355014221324"/>
    <inertia ixx="0.00011741975307643423" iyy="0.00012506730248329706" izz="0.000100988308472931" ixy="3.467542980046352e-05" iyz="-1.1418298465589068e-05" ixz="-4.863723040985073e-06"/>
  </inertial>
  <visual>
    <origin xyz="-0.079416 -0.123528 -0.01235" rpy="0 0 0"/>
    <geometry>
      <mesh filename="meshes/leg_41femur_v4_31.stl" scale="0.001 0.001 0.001"/>
    </geometry>
    <material name="silver"/>
    <material/>
  </visual>
  <collision>
    <origin xyz="-0.079416 -0.123528 -0.01235" rpy="0 0 0"/>
    <geometry>
      <mesh filename="meshes/leg_41femur_v4_31.stl" scale="0.001 0.001 0.001"/>
    </geometry>
  </collision>
</link>

<link name="leg_41MG996_v3_111Body_111">
  <inertial>
    <origin xyz="0.020774597678633516 -0.006532068153070586 -4.5531993872471865e-07" rpy="0 0 0"/>
    <mass value="0.20707552542569635"/>
    <inertia ixx="3.126222199552331e-05" iyy="3.284640572262e-05" izz="5.072602799896086e-05" ixy="-4.127658227148171e-06" iyz="2.761811612739251e-12" ixz="3.839666215185722e-12"/>
  </inertial>
  <visual>
    <origin xyz="-0.099627 -0.145154 -0.075792" rpy="0 0 0"/>
    <geometry>
      <mesh filename="meshes/leg_41MG996_v3_111Body_111.stl" scale="0.001 0.001 0.001"/>
    </geometry>
    <material name="silver"/>
    <material/>
  </visual>
  <collision>
    <origin xyz="-0.099627 -0.145154 -0.075792" rpy="0 0 0"/>
    <geometry>
      <mesh filename="meshes/leg_41MG996_v3_111Body_111.stl" scale="0.001 0.001 0.001"/>
    </geometry>
  </collision>
</link>

<link name="leg_41tibia_v5_31">
  <inertial>
    <origin xyz="0.03995100484200578 0.025800951093326502 0.013219764065198578" rpy="0 0 0"/>
    <mass value="0.09285304614043148"/>
    <inertia ixx="5.130986387543151e-05" iyy="5.664323795965707e-05" izz="9.868903018824676e-05" ixy="-4.7553797670652495e-05" iyz="-5.19372578075398e-06" ixz="-6.548081736350211e-06"/>
  </inertial>
  <visual>
    <origin xyz="-0.097223 -0.127122 -0.070542" rpy="0 0 0"/>
    <geometry>
      <mesh filename="meshes/leg_41tibia_v5_31.stl" scale="0.001 0.001 0.001"/>
    </geometry>
    <material name="silver"/>
    <material/>
  </visual>
  <collision>
    <origin xyz="-0.097223 -0.127122 -0.070542" rpy="0 0 0"/>
    <geometry>
      <mesh filename="meshes/leg_41tibia_v5_31.stl" scale="0.001 0.001 0.001"/>
    </geometry>
  </collision>
</link>

<link name="leg_41shield_v2_31">
  <inertial>
    <origin xyz="-0.022724239731226226 -0.022723903452308875 0.00795640943465542" rpy="0 0 0"/>
    <mass value="0.09400422482344938"/>
    <inertia ixx="5.845346139379901e-05" iyy="5.8453134327359976e-05" izz="0.00011235877990886309" ixy="-4.05725750517341e-05" iyz="-2.7243960037267277e-06" ixz="-2.724973858622172e-06"/>
  </inertial>
  <visual>
    <origin xyz="-0.171148 -0.185067 -0.091792" rpy="0 0 0"/>
    <geometry>
      <mesh filename="meshes/leg_41shield_v2_31.stl" scale="0.001 0.001 0.001"/>
    </geometry>
    <material name="silver"/>
    <material/>
  </visual>
  <collision>
    <origin xyz="-0.171148 -0.185067 -0.091792" rpy="0 0 0"/>
    <geometry>
      <mesh filename="meshes/leg_41shield_v2_31.stl" scale="0.001 0.001 0.001"/>
    </geometry>
  </collision>
</link>

<link name="leg_51coxa_v2_41">
  <inertial>
    <origin xyz="0.025372840494156 -0.00015174123084919804 -0.024879639248893873" rpy="0 0 0"/>
    <mass value="0.07898637744159479"/>
    <inertia ixx="4.963139741329645e-05" iyy="7.128210636066386e-05" izz="2.4265877776945624e-05" ixy="2.1127014631553387e-07" iyz="3.9907358386099736e-08" ixz="-5.949787137622529e-06"/>
  </inertial>
  <visual>
    <origin xyz="-0.08115 0.0 -0.02405" rpy="0 0 0"/>
    <geometry>
      <mesh filename="meshes/leg_51coxa_v2_41.stl" scale="0.001 0.001 0.001"/>
    </geometry>
    <material name="silver"/>
    <material/>
  </visual>
  <collision>
    <origin xyz="-0.08115 0.0 -0.02405" rpy="0 0 0"/>
    <geometry>
      <mesh filename="meshes/leg_51coxa_v2_41.stl" scale="0.001 0.001 0.001"/>
    </geometry>
  </collision>
</link>

<link name="leg_51MG996_v3_141Body_141">
  <inertial>
    <origin xyz="-0.005250000412504244 -0.008258413777840338 -0.02452120215015828" rpy="0 0 0"/>
    <mass value="0.20707552542569635"/>
    <inertia ixx="5.072602799895641e-05" iyy="3.618197208621636e-05" izz="2.7926655631923484e-05" ixy="-7.621577658269499e-13" iyz="-7.920918635483894e-07" ixz="-4.6679501491389205e-12"/>
  </inertial>
  <visual>
    <origin xyz="-0.1294 -0.007 -0.0268" rpy="0 0 0"/>
    <geometry>
      <mesh filename="meshes/leg_51MG996_v3_141Body_141.stl" scale="0.001 0.001 0.001"/>
    </geometry>
    <material name="silver"/>
    <material/>
  </visual>
  <collision>
    <origin xyz="-0.1294 -0.007 -0.0268" rpy="0 0 0"/>
    <geometry>
      <mesh filename="meshes/leg_51MG996_v3_141Body_141.stl" scale="0.001 0.001 0.001"/>
    </geometry>
  </collision>
</link>

<link name="leg_51femur_v4_41">
  <inertial>
    <origin xyz="0.0031247845947252467 -0.022881099732135056 0.04552760716696073" rpy="0 0 0"/>
    <mass value="0.2061355014221324"/>
    <inertia ixx="0.00015591895758032917" iyy="8.656809797940191e-05" izz="0.0001009883084729297" ixy="3.823774703431824e-06" iyz="-4.6347847305359605e-06" ixz="-1.1513127818724026e-05"/>
  </inertial>
  <visual>
    <origin xyz="-0.12415 -0.01705 -0.01235" rpy="0 0 0"/>
    <geometry>
      <mesh filename="meshes/leg_51femur_v4_41.stl" scale="0.001 0.001 0.001"/>
    </geometry>
    <material name="silver"/>
    <material/>
  </visual>
  <collision>
    <origin xyz="-0.12415 -0.01705 -0.01235" rpy="0 0 0"/>
    <geometry>
      <mesh filename="meshes/leg_51femur_v4_41.stl" scale="0.001 0.001 0.001"/>
    </geometry>
  </collision>
</link>

<link name="leg_51MG996_v3_131Body_131">
  <inertial>
    <origin xyz="0.010071480472007177 -0.019308413777840337 -4.5531993872471865e-07" rpy="0 0 0"/>
    <mass value="0.20707552542569635"/>
    <inertia ixx="2.79266556319237e-05" iyy="3.618197208621419e-05" izz="5.072602799895479e-05" ixy="7.920918635484066e-07" iyz="-7.621577759913453e-13" ixz="4.6679504879520994e-12"/>
  </inertial>
  <visual>
    <origin xyz="-0.153733 -0.01805 -0.075792" rpy="0 0 0"/>
    <geometry>
      <mesh filename="meshes/leg_51MG996_v3_131Body_131.stl" scale="0.001 0.001 0.001"/>
    </geometry>
    <material name="silver"/>
    <material/>
  </visual>
  <collision>
    <origin xyz="-0.153733 -0.01805 -0.075792" rpy="0 0 0"/>
    <geometry>
      <mesh filename="meshes/leg_51MG996_v3_131Body_131.stl" scale="0.001 0.001 0.001"/>
    </geometry>
  </collision>
</link>

<link name="leg_51tibia_v5_41">
  <inertial>
    <origin xyz="0.04649371100105623 -0.010005948932876001 0.013219764065198578" rpy="0 0 0"/>
    <mass value="0.09285304614043148"/>
    <inertia ixx="6.42275324689147e-06" iyy="0.00010153034858819635" izz="9.868903018824633e-05" ixy="2.6666870421129506e-06" iyz="9.576742803426926e-07" ixz="-8.302711718731221e-06"/>
  </inertial>
  <visual>
    <origin xyz="-0.139283 -0.007 -0.070542" rpy="0 0 0"/>
    <geometry>
      <mesh filename="meshes/leg_51tibia_v5_41.stl" scale="0.001 0.001 0.001"/>
    </geometry>
    <material name="silver"/>
    <material/>
  </visual>
  <collision>
    <origin xyz="-0.139283 -0.007 -0.070542" rpy="0 0 0"/>
    <geometry>
      <mesh filename="meshes/leg_51tibia_v5_41.stl" scale="0.001 0.001 0.001"/>
    </geometry>
  </collision>
</link>

<link name="leg_51shield_v2_41">
  <inertial>
    <origin xyz="-0.03213746191944117 3.214487110433234e-07 0.00795640943465542" rpy="0 0 0"/>
    <mass value="0.09400422482344938"/>
    <inertia ixx="1.788072280884496e-05" iyy="9.902587291231446e-05" izz="0.00011235877990886439" ixy="-1.6353321903020065e-10" iyz="4.086051154004143e-10" ixz="-3.853286382860411e-06"/>
  </inertial>
  <visual>
    <origin xyz="-0.23253 0.0043 -0.091792" rpy="0 0 0"/>
    <geometry>
      <mesh filename="meshes/leg_51shield_v2_41.stl" scale="0.001 0.001 0.001"/>
    </geometry>
    <material name="silver"/>
    <material/>
  </visual>
  <collision>
    <origin xyz="-0.23253 0.0043 -0.091792" rpy="0 0 0"/>
    <geometry>
      <mesh filename="meshes/leg_51shield_v2_41.stl" scale="0.001 0.001 0.001"/>
    </geometry>
  </collision>
</link>

<link name="leg_61coxa_v2_51">
  <inertial>
    <origin xyz="0.01783423144364 -0.018048825950272948 -0.024879639248893873" rpy="0 0 0"/>
    <mass value="0.07898637744159479"/>
    <inertia ixx="6.0668022033295486e-05" iyy="6.024548174066429e-05" izz="2.4265877776945407e-05" ixy="1.0825354473683593e-05" iyz="4.235353595363449e-06" ixz="-4.178916067895342e-06"/>
  </inertial>
  <visual>
    <origin xyz="-0.061066 0.081066 -0.02405" rpy="0 0 0"/>
    <geometry>
      <mesh filename="meshes/leg_61coxa_v2_51.stl" scale="0.001 0.001 0.001"/>
    </geometry>
    <material name="silver"/>
    <material/>
  </visual>
  <collision>
    <origin xyz="-0.061066 0.081066 -0.02405" rpy="0 0 0"/>
    <geometry>
      <mesh filename="meshes/leg_61coxa_v2_51.stl" scale="0.001 0.001 0.001"/>
    </geometry>
  </collision>
</link>

<link name="leg_61MG996_v3_161Body_161">
  <inertial>
    <origin xyz="-0.009552020490935786 -0.0021276453407579887 -0.02452120215015828" rpy="0 0 0"/>
    <mass value="0.20707552542569635"/>
    <inertia ixx="4.3453999280428524e-05" iyy="4.3454000804743704e-05" izz="2.7926655631925652e-05" ixy="-7.272027956370299e-06" iyz="-5.600902272985479e-07" ixz="-5.600968287769586e-07"/>
  </inertial>
  <visual>
    <origin xyz="-0.100134 0.110234 -0.0268" rpy="0 0 0"/>
    <geometry>
      <mesh filename="meshes/leg_61MG996_v3_161Body_161.stl" scale="0.001 0.001 0.001"/>
    </geometry>
    <material name="silver"/>
    <material/>
  </visual>
  <collision>
    <origin xyz="-0.100134 0.110234 -0.0268" rpy="0 0 0"/>
    <geometry>
      <mesh filename="meshes/leg_61MG996_v3_161Body_161.stl" scale="0.001 0.001 0.001"/>
    </geometry>
  </collision>
</link>

<link name="leg_61femur_v4_51">
  <inertial>
    <origin xyz="-0.013969841069092034 -0.018388579255638304 0.04552760716696073" rpy="0 0 0"/>
    <mass value="0.2061355014221324"/>
    <inertia ixx="0.00012506730248329663" iyy="0.0001174197530764338" izz="0.00010098830847293013" ixy="-3.467542980046395e-05" iyz="4.863723040985507e-06" ixz="-1.1418298465589068e-05"/>
  </inertial>
  <visual>
    <origin xyz="-0.103528 0.099416 -0.01235" rpy="0 0 0"/>
    <geometry>
      <mesh filename="meshes/leg_61femur_v4_51.stl" scale="0.001 0.001 0.001"/>
    </geometry>
    <material name="silver"/>
    <material/>
  </visual>
  <collision>
    <origin xyz="-0.103528 0.099416 -0.01235" rpy="0 0 0"/>
    <geometry>
      <mesh filename="meshes/leg_61femur_v4_51.stl" scale="0.001 0.001 0.001"/>
    </geometry>
  </collision>
</link>

<link name="leg_61MG996_v3_171Body_171">
  <inertial>
    <origin xyz="-0.006532068153065493 -0.020774597678628312 -4.5531993872471865e-07" rpy="0 0 0"/>
    <mass value="0.20707552542569635"/>
    <inertia ixx="3.284640572262e-05" iyy="3.126222199552244e-05" izz="5.072602799896086e-05" ixy="4.1276582271490385e-06" iyz="-3.8396655646644184e-12" ixz="2.761811612739251e-12"/>
  </inertial>
  <visual>
    <origin xyz="-0.125154 0.119627 -0.075792" rpy="0 0 0"/>
    <geometry>
      <mesh filename="meshes/leg_61MG996_v3_171Body_171.stl" scale="0.001 0.001 0.001"/>
    </geometry>
    <material name="silver"/>
    <material/>
  </visual>
  <collision>
    <origin xyz="-0.125154 0.119627 -0.075792" rpy="0 0 0"/>
    <geometry>
      <mesh filename="meshes/leg_61MG996_v3_171Body_171.stl" scale="0.001 0.001 0.001"/>
    </geometry>
  </collision>
</link>

<link name="leg_61tibia_v5_51">
  <inertial>
    <origin xyz="0.025800951093331637 -0.03995100484200062 0.013219764065198578" rpy="0 0 0"/>
    <mass value="0.09285304614043148"/>
    <inertia ixx="5.664323795965707e-05" iyy="5.130986387543151e-05" izz="9.868903018824763e-05" ixy="4.755379767065271e-05" iyz="6.548081736350211e-06" ixz="-5.193725780753547e-06"/>
  </inertial>
  <visual>
    <origin xyz="-0.107122 0.117223 -0.070542" rpy="0 0 0"/>
    <geometry>
      <mesh filename="meshes/leg_61tibia_v5_51.stl" scale="0.001 0.001 0.001"/>
    </geometry>
    <material name="silver"/>
    <material/>
  </visual>
  <collision>
    <origin xyz="-0.107122 0.117223 -0.070542" rpy="0 0 0"/>
    <geometry>
      <mesh filename="meshes/leg_61tibia_v5_51.stl" scale="0.001 0.001 0.001"/>
    </geometry>
  </collision>
</link>

<link name="leg_61shield_v2_51">
  <inertial>
    <origin xyz="-0.022723903452303768 0.022724239731231444 0.00795640943465542" rpy="0 0 0"/>
    <mass value="0.09400422482344938"/>
    <inertia ixx="5.8453134327360844e-05" iyy="5.845346139379858e-05" izz="0.00011235877990886396" ixy="4.0572575051733666e-05" iyz="2.724973858622172e-06" ixz="-2.724396003726511e-06"/>
  </inertial>
  <visual>
    <origin xyz="-0.165067 0.191148 -0.091792" rpy="0 0 0"/>
    <geometry>
      <mesh filename="meshes/leg_61shield_v2_51.stl" scale="0.001 0.001 0.001"/>
    </geometry>
    <material name="silver"/>
    <material/>
  </visual>
  <collision>
    <origin xyz="-0.165067 0.191148 -0.091792" rpy="0 0 0"/>
    <geometry>
      <mesh filename="meshes/leg_61shield_v2_51.stl" scale="0.001 0.001 0.001"/>
    </geometry>
  </collision>
</link>

<joint name="Rigido_1" type="fixed">
  <origin xyz="-0.067006 -0.094431 0.014" rpy="0 0 0"/>
  <parent link="base_link"/>
  <child link="leg_11MG996_v31Body1"/>
</joint>

<joint name="Rigido_4" type="fixed">
  <origin xyz="-0.0462 -0.00525 0.014" rpy="0 0 0"/>
  <parent link="base_link"/>
  <child link="leg_21MG996_v3_31Body_31"/>
</joint>

<joint name="Rigido_5" type="fixed">
  <origin xyz="-0.040065 0.052641 0.014" rpy="0 0 0"/>
  <parent link="base_link"/>
  <child link="leg_31MG996_v3_81Body_81"/>
</joint>

<joint name="Rigido_6" type="fixed">
  <origin xyz="0.040065 0.052641 0.014" rpy="0 0 0"/>
  <parent link="base_link"/>
  <child link="leg_41MG996_v3_91Body_91"/>
</joint>

<joint name="Rigido_7" type="fixed">
  <origin xyz="0.0462 0.00525 0.014" rpy="0 0 0"/>
  <parent link="base_link"/>
  <child link="leg_51MG996_v3_121Body_121"/>
</joint>

<joint name="Rigido_8" type="fixed">
  <origin xyz="0.040065 -0.052641 0.014" rpy="0 0 0"/>
  <parent link="base_link"/>
  <child link="leg_61MG996_v3_151Body_151"/>
</joint>

<joint name="leg_11_Rivoluzione 1" type="revolute">
  <origin xyz="0.006505 0.01393 0.01005" rpy="0 0 0"/>
  <parent link="leg_11MG996_v31Body1"/>
  <child link="leg_11coxa_v21"/>
  <axis xyz="0.0 0.0 1.0"/>
  <limit upper="1.570796" lower="-1.570796" effort="100" velocity="100"/>
</joint>
<transmission name="leg_11_Rivoluzione 1_tran">
  <type>transmission_interface/SimpleTransmission</type>
  <joint name="leg_11_Rivoluzione 1">
    <hardwareInterface>PositionJointInterface</hardwareInterface>
  </joint>
  <actuator name="leg_11_Rivoluzione 1_actr">
    <hardwareInterface>PositionJointInterface</hardwareInterface>
    <mechanicalReduction>1</mechanicalReduction>
  </actuator>
</transmission>

<joint name="leg_11_Rigido 2" type="fixed">
  <origin xyz="-0.029168 -0.039067 0.00275" rpy="0 0 0"/>
  <parent link="leg_11coxa_v21"/>
  <child link="leg_11MG996_v3_21Body_21"/>
</joint>

<joint name="leg_11_Rivoluzione 3" type="revolute">
  <origin xyz="0.010819 -0.003394 -0.01445" rpy="0 0 0"/>
  <parent link="leg_11MG996_v3_21Body_21"/>
  <child link="leg_11femur_v41"/>
  <axis xyz="0.707107 -0.707107 0.0"/>
  <limit upper="2.443461" lower="-0.872665" effort="100" velocity="100"/>
</joint>
<transmission name="leg_11_Rivoluzione 3_tran">
  <type>transmission_interface/SimpleTransmission</type>
  <joint name="leg_11_Rivoluzione 3">
    <hardwareInterface>PositionJointInterface</hardwareInterface>
  </joint>
  <actuator name="leg_11_Rivoluzione 3_actr">
    <hardwareInterface>PositionJointInterface</hardwareInterface>
    <mechanicalReduction>1</mechanicalReduction>
  </actuator>
</transmission>

<joint name="leg_11_Rivoluzione 4" type="revolute">
  <origin xyz="-0.020211 -0.021626 0.063442" rpy="0 0 0"/>
  <parent link="leg_11femur_v41"/>
  <child link="leg_11MG996_v3_11Body_11"/>
  <axis xyz="-0.707107 0.707107 0.0"/>
  <limit upper="1.570796" lower="-0.785398" effort="100" velocity="100"/>
</joint>
<transmission name="leg_11_Rivoluzione 4_tran">
  <type>transmission_interface/SimpleTransmission</type>
  <joint name="leg_11_Rivoluzione 4">
    <hardwareInterface>PositionJointInterface</hardwareInterface>
  </joint>
  <actuator name="leg_11_Rivoluzione 4_actr">
    <hardwareInterface>PositionJointInterface</hardwareInterface>
    <mechanicalReduction>1</mechanicalReduction>
  </actuator>
</transmission>

<joint name="leg_11_Rigido 5" type="fixed">
  <origin xyz="0.002404 0.018031 -0.00525" rpy="0 0 0"/>
  <parent link="leg_11MG996_v3_11Body_11"/>
  <child link="leg_11tibia_v51"/>
</joint>

<joint name="leg_11_Rigido 6" type="fixed">
  <origin xyz="-0.073926 -0.057945 0.02125" rpy="0 0 0"/>
  <parent link="leg_11tibia_v51"/>
  <child link="leg_11shield_v21"/>
</joint>

<joint name="leg_21_Rivoluzione 1" type="revolute">
  <origin xyz="-0.03495 0.00525 0.01005" rpy="0 0 0"/>
  <parent link="leg_21MG996_v3_31Body_31"/>
  <child link="leg_21coxa_v2_11"/>
  <axis xyz="0.0 0.0 1.0"/>
  <limit upper="1.570796" lower="-1.570796" effort="100" velocity="100"/>
</joint>
<transmission name="leg_21_Rivoluzione 1_tran">
  <type>transmission_interface/SimpleTransmission</type>
  <joint name="leg_21_Rivoluzione 1">
    <hardwareInterface>PositionJointInterface</hardwareInterface>
  </joint>
  <actuator name="leg_21_Rivoluzione 1_actr">
    <hardwareInterface>PositionJointInterface</hardwareInterface>
    <mechanicalReduction>1</mechanicalReduction>
  </actuator>
</transmission>

<joint name="leg_21_Rigido 2" type="fixed">
  <origin xyz="-0.04825 -0.007 0.00275" rpy="0 0 0"/>
  <parent link="leg_21coxa_v2_11"/>
  <child link="leg_21MG996_v3_51Body_51"/>
</joint>

<joint name="leg_21_Rivoluzione 3" type="revolute">
  <origin xyz="0.00525 -0.01005 -0.01445" rpy="0 0 0"/>
  <parent link="leg_21MG996_v3_51Body_51"/>
  <child link="leg_21femur_v4_11"/>
  <axis xyz="0.0 -1.0 0.0"/>
  <limit upper="2.443461" lower="-0.872665" effort="100" velocity="100"/>
</joint>
<transmission name="leg_21_Rivoluzione 3_tran">
  <type>transmission_interface/SimpleTransmission</type>
  <joint name="leg_21_Rivoluzione 3">
    <hardwareInterface>PositionJointInterface</hardwareInterface>
  </joint>
  <actuator name="leg_21_Rivoluzione 3_actr">
    <hardwareInterface>PositionJointInterface</hardwareInterface>
    <mechanicalReduction>1</mechanicalReduction>
  </actuator>
</transmission>

<joint name="leg_21_Rivoluzione 4" type="revolute">
  <origin xyz="-0.029583 -0.001 0.063442" rpy="0 0 0"/>
  <parent link="leg_21femur_v4_11"/>
  <child link="leg_21MG996_v3_41Body_41"/>
  <axis xyz="-0.0 1.0 0.0"/>
  <limit upper="1.570796" lower="-0.785398" effort="100" velocity="100"/>
</joint>
<transmission name="leg_21_Rivoluzione 4_tran">
  <type>transmission_interface/SimpleTransmission</type>
  <joint name="leg_21_Rivoluzione 4">
    <hardwareInterface>PositionJointInterface</hardwareInterface>
  </joint>
  <actuator name="leg_21_Rivoluzione 4_actr">
    <hardwareInterface>PositionJointInterface</hardwareInterface>
    <mechanicalReduction>1</mechanicalReduction>
  </actuator>
</transmission>

<joint name="leg_21_Rigido 5" type="fixed">
  <origin xyz="0.01445 0.01105 -0.00525" rpy="0 0 0"/>
  <parent link="leg_21MG996_v3_41Body_41"/>
  <child link="leg_21tibia_v5_11"/>
</joint>

<joint name="leg_21_Rigido 6" type="fixed">
  <origin xyz="-0.093247 0.0113 0.02125" rpy="0 0 0"/>
  <parent link="leg_21tibia_v5_11"/>
  <child link="leg_21shield_v2_11"/>
</joint>

<joint name="leg_31_Rivoluzione 1" type="revolute">
  <origin xyz="-0.021001 0.028425 0.01005" rpy="0 0 0"/>
  <parent link="leg_31MG996_v3_81Body_81"/>
  <child link="leg_31coxa_v2_21"/>
  <axis xyz="0.0 0.0 1.0"/>
  <limit upper="1.570796" lower="-1.570796" effort="100" velocity="100"/>
</joint>
<transmission name="leg_31_Rivoluzione 1_tran">
  <type>transmission_interface/SimpleTransmission</type>
  <joint name="leg_31_Rivoluzione 1">
    <hardwareInterface>PositionJointInterface</hardwareInterface>
  </joint>
  <actuator name="leg_31_Rivoluzione 1_actr">
    <hardwareInterface>PositionJointInterface</hardwareInterface>
    <mechanicalReduction>1</mechanicalReduction>
  </actuator>
</transmission>

<joint name="leg_31_Rigido 2" type="fixed">
  <origin xyz="-0.039068 0.029168 0.00275" rpy="0 0 0"/>
  <parent link="leg_31coxa_v2_21"/>
  <child link="leg_31MG996_v3_61Body_61"/>
</joint>

<joint name="leg_31_Rivoluzione 3" type="revolute">
  <origin xyz="-0.003394 -0.010818 -0.01445" rpy="0 0 0"/>
  <parent link="leg_31MG996_v3_61Body_61"/>
  <child link="leg_31femur_v4_21"/>
  <axis xyz="-0.707107 -0.707107 0.0"/>
  <limit upper="2.443461" lower="-0.872665" effort="100" velocity="100"/>
</joint>
<transmission name="leg_31_Rivoluzione 3_tran">
  <type>transmission_interface/SimpleTransmission</type>
  <joint name="leg_31_Rivoluzione 3">
    <hardwareInterface>PositionJointInterface</hardwareInterface>
  </joint>
  <actuator name="leg_31_Rivoluzione 3_actr">
    <hardwareInterface>PositionJointInterface</hardwareInterface>
    <mechanicalReduction>1</mechanicalReduction>
  </actuator>
</transmission>

<joint name="leg_31_Rivoluzione 4" type="revolute">
  <origin xyz="-0.021626 0.020211 0.063442" rpy="0 0 0"/>
  <parent link="leg_31femur_v4_21"/>
  <child link="leg_31MG996_v3_71Body_71"/>
  <axis xyz="0.707107 0.707107 0.0"/>
  <limit upper="1.570796" lower="-0.785398" effort="100" velocity="100"/>
</joint>
<transmission name="leg_31_Rivoluzione 4_tran">
  <type>transmission_interface/SimpleTransmission</type>
  <joint name="leg_31_Rivoluzione 4">
    <hardwareInterface>PositionJointInterface</hardwareInterface>
  </joint>
  <actuator name="leg_31_Rivoluzione 4_actr">
    <hardwareInterface>PositionJointInterface</hardwareInterface>
    <mechanicalReduction>1</mechanicalReduction>
  </actuator>
</transmission>

<joint name="leg_31_Rigido 5" type="fixed">
  <origin xyz="0.018032 -0.002404 -0.00525" rpy="0 0 0"/>
  <parent link="leg_31MG996_v3_71Body_71"/>
  <child link="leg_31tibia_v5_21"/>
</joint>

<joint name="leg_31_Rigido 6" type="fixed">
  <origin xyz="-0.057945 0.073925 0.02125" rpy="0 0 0"/>
  <parent link="leg_31tibia_v5_21"/>
  <child link="leg_31shield_v2_21"/>
</joint>

<joint name="leg_41_Rivoluzione 1" type="revolute">
  <origin xyz="0.021001 0.028425 0.01005" rpy="0 0 0"/>
  <parent link="leg_41MG996_v3_91Body_91"/>
  <child link="leg_41coxa_v2_31"/>
  <axis xyz="0.0 0.0 1.0"/>
  <limit upper="1.570796" lower="-1.570796" effort="100" velocity="100"/>
</joint>
<transmission name="leg_41_Rivoluzione 1_tran">
  <type>transmission_interface/SimpleTransmission</type>
  <joint name="leg_41_Rivoluzione 1">
    <hardwareInterface>PositionJointInterface</hardwareInterface>
  </joint>
  <actuator name="leg_41_Rivoluzione 1_actr">
    <hardwareInterface>PositionJointInterface</hardwareInterface>
    <mechanicalReduction>1</mechanicalReduction>
  </actuator>
</transmission>

<joint name="leg_41_Rigido 2" type="fixed">
  <origin xyz="0.029168 0.039068 0.00275" rpy="0 0 0"/>
  <parent link="leg_41coxa_v2_31"/>
  <child link="leg_41MG996_v3_101Body_101"/>
</joint>

<joint name="leg_41_Rivoluzione 3" type="revolute">
  <origin xyz="-0.010818 0.003394 -0.01445" rpy="0 0 0"/>
  <parent link="leg_41MG996_v3_101Body_101"/>
  <child link="leg_41femur_v4_31"/>
  <axis xyz="-0.707107 0.707107 0.0"/>
  <limit upper="2.443461" lower="-0.872665" effort="100" velocity="100"/>
</joint>
<transmission name="leg_41_Rivoluzione 3_tran">
  <type>transmission_interface/SimpleTransmission</type>
  <joint name="leg_41_Rivoluzione 3">
    <hardwareInterface>PositionJointInterface</hardwareInterface>
  </joint>
  <actuator name="leg_41_Rivoluzione 3_actr">
    <hardwareInterface>PositionJointInterface</hardwareInterface>
    <mechanicalReduction>1</mechanicalReduction>
  </actuator>
</transmission>

<joint name="leg_41_Rivoluzione 4" type="revolute">
  <origin xyz="0.020211 0.021626 0.063442" rpy="0 0 0"/>
  <parent link="leg_41femur_v4_31"/>
  <child link="leg_41MG996_v3_111Body_111"/>
  <axis xyz="0.707107 -0.707107 0.0"/>
  <limit upper="1.570796" lower="-0.785398" effort="100" velocity="100"/>
</joint>
<transmission name="leg_41_Rivoluzione 4_tran">
  <type>transmission_interface/SimpleTransmission</type>
  <joint name="leg_41_Rivoluzione 4">
    <hardwareInterface>PositionJointInterface</hardwareInterface>
  </joint>
  <actuator name="leg_41_Rivoluzione 4_actr">
    <hardwareInterface>PositionJointInterface</hardwareInterface>
    <mechanicalReduction>1</mechanicalReduction>
  </actuator>
</transmission>

<joint name="leg_41_Rigido 5" type="fixed">
  <origin xyz="-0.002404 -0.018032 -0.00525" rpy="0 0 0"/>
  <parent link="leg_41MG996_v3_111Body_111"/>
  <child link="leg_41tibia_v5_31"/>
</joint>

<joint name="leg_41_Rigido 6" type="fixed">
  <origin xyz="0.073925 0.057945 0.02125" rpy="0 0 0"/>
  <parent link="leg_41tibia_v5_31"/>
  <child link="leg_41shield_v2_31"/>
</joint>

<joint name="leg_51_Rivoluzione 1" type="revolute">
  <origin xyz="0.03495 -0.00525 0.01005" rpy="0 0 0"/>
  <parent link="leg_51MG996_v3_121Body_121"/>
  <child link="leg_51coxa_v2_41"/>
  <axis xyz="0.0 0.0 1.0"/>
  <limit upper="1.570796" lower="-1.570796" effort="100" velocity="100"/>
</joint>
<transmission name="leg_51_Rivoluzione 1_tran">
  <type>transmission_interface/SimpleTransmission</type>
  <joint name="leg_51_Rivoluzione 1">
    <hardwareInterface>PositionJointInterface</hardwareInterface>
  </joint>
  <actuator name="leg_51_Rivoluzione 1_actr">
    <hardwareInterface>PositionJointInterface</hardwareInterface>
    <mechanicalReduction>1</mechanicalReduction>
  </actuator>
</transmission>

<joint name="leg_51_Rigido 2" type="fixed">
  <origin xyz="0.04825 0.007 0.00275" rpy="0 0 0"/>
  <parent link="leg_51coxa_v2_41"/>
  <child link="leg_51MG996_v3_141Body_141"/>
</joint>

<joint name="leg_51_Rivoluzione 3" type="revolute">
  <origin xyz="-0.00525 0.01005 -0.01445" rpy="0 0 0"/>
  <parent link="leg_51MG996_v3_141Body_141"/>
  <child link="leg_51femur_v4_41"/>
  <axis xyz="0.0 1.0 0.0"/>
  <limit upper="2.443461" lower="-0.872665" effort="100" velocity="100"/>
</joint>
<transmission name="leg_51_Rivoluzione 3_tran">
  <type>transmission_interface/SimpleTransmission</type>
  <joint name="leg_51_Rivoluzione 3">
    <hardwareInterface>PositionJointInterface</hardwareInterface>
  </joint>
  <actuator name="leg_51_Rivoluzione 3_actr">
    <hardwareInterface>PositionJointInterface</hardwareInterface>
    <mechanicalReduction>1</mechanicalReduction>
  </actuator>
</transmission>

<joint name="leg_51_Rivoluzione 4" type="revolute">
  <origin xyz="0.029583 0.001 0.063442" rpy="0 0 0"/>
  <parent link="leg_51femur_v4_41"/>
  <child link="leg_51MG996_v3_131Body_131"/>
  <axis xyz="-0.0 -1.0 0.0"/>
  <limit upper="1.570796" lower="-0.785398" effort="100" velocity="100"/>
</joint>
<transmission name="leg_51_Rivoluzione 4_tran">
  <type>transmission_interface/SimpleTransmission</type>
  <joint name="leg_51_Rivoluzione 4">
    <hardwareInterface>PositionJointInterface</hardwareInterface>
  </joint>
  <actuator name="leg_51_Rivoluzione 4_actr">
    <hardwareInterface>PositionJointInterface</hardwareInterface>
    <mechanicalReduction>1</mechanicalReduction>
  </actuator>
</transmission>

<joint name="leg_51_Rigido 5" type="fixed">
  <origin xyz="-0.01445 -0.01105 -0.00525" rpy="0 0 0"/>
  <parent link="leg_51MG996_v3_131Body_131"/>
  <child link="leg_51tibia_v5_41"/>
</joint>

<joint name="leg_51_Rigido 6" type="fixed">
  <origin xyz="0.093247 -0.0113 0.02125" rpy="0 0 0"/>
  <parent link="leg_51tibia_v5_41"/>
  <child link="leg_51shield_v2_41"/>
</joint>

<joint name="leg_61_Rivoluzione 1" type="revolute">
  <origin xyz="0.021001 -0.028425 0.01005" rpy="0 0 0"/>
  <parent link="leg_61MG996_v3_151Body_151"/>
  <child link="leg_61coxa_v2_51"/>
  <axis xyz="0.0 0.0 1.0"/>
  <limit upper="1.570796" lower="-1.570796" effort="100" velocity="100"/>
</joint>
<transmission name="leg_61_Rivoluzione 1_tran">
  <type>transmission_interface/SimpleTransmission</type>
  <joint name="leg_61_Rivoluzione 1">
    <hardwareInterface>PositionJointInterface</hardwareInterface>
  </joint>
  <actuator name="leg_61_Rivoluzione 1_actr">
    <hardwareInterface>PositionJointInterface</hardwareInterface>
    <mechanicalReduction>1</mechanicalReduction>
  </actuator>
</transmission>

<joint name="leg_61_Rigido 2" type="fixed">
  <origin xyz="0.039068 -0.029168 0.00275" rpy="0 0 0"/>
  <parent link="leg_61coxa_v2_51"/>
  <child link="leg_61MG996_v3_161Body_161"/>
</joint>

<joint name="leg_61_Rivoluzione 3" type="revolute">
  <origin xyz="0.003394 0.010818 -0.01445" rpy="0 0 0"/>
  <parent link="leg_61MG996_v3_161Body_161"/>
  <child link="leg_61femur_v4_51"/>
  <axis xyz="0.707107 0.707107 0.0"/>
  <limit upper="2.443461" lower="-0.872665" effort="100" velocity="100"/>
</joint>
<transmission name="leg_61_Rivoluzione 3_tran">
  <type>transmission_interface/SimpleTransmission</type>
  <joint name="leg_61_Rivoluzione 3">
    <hardwareInterface>PositionJointInterface</hardwareInterface>
  </joint>
  <actuator name="leg_61_Rivoluzione 3_actr">
    <hardwareInterface>PositionJointInterface</hardwareInterface>
    <mechanicalReduction>1</mechanicalReduction>
  </actuator>
</transmission>

<joint name="leg_61_Rivoluzione 4" type="revolute">
  <origin xyz="0.021626 -0.020211 0.063442" rpy="0 0 0"/>
  <parent link="leg_61femur_v4_51"/>
  <child link="leg_61MG996_v3_171Body_171"/>
  <axis xyz="-0.707107 -0.707107 0.0"/>
  <limit upper="1.570796" lower="-0.785398" effort="100" velocity="100"/>
</joint>
<transmission name="leg_61_Rivoluzione 4_tran">
  <type>transmission_interface/SimpleTransmission</type>
  <joint name="leg_61_Rivoluzione 4">
    <hardwareInterface>PositionJointInterface</hardwareInterface>
  </joint>
  <actuator name="leg_61_Rivoluzione 4_actr">
    <hardwareInterface>PositionJointInterface</hardwareInterface>
    <mechanicalReduction>1</mechanicalReduction>
  </actuator>
</transmission>

<joint name="leg_61_Rigido 5" type="fixed">
  <origin xyz="-0.018032 0.002404 -0.00525" rpy="0 0 0"/>
  <parent link="leg_61MG996_v3_171Body_171"/>
  <child link="leg_61tibia_v5_51"/>
</joint>

<joint name="leg_61_Rigido 6" type="fixed">
  <origin xyz="0.057945 -0.073925 0.02125" rpy="0 0 0"/>
  <parent link="leg_61tibia_v5_51"/>
  <child link="leg_61shield_v2_51"/>
</joint>

</robot>
